Exception in thread django-main-thread:
Traceback (most recent call last):
  File "/usr/lib/python3.13/threading.py", line 1041, in _bootstrap_inner
    self.run()
    ~~~~~~~~^^
  File "/usr/lib/python3.13/threading.py", line 992, in run
    self._target(*self._args, **self._kwargs)
    ~~~~~~~~~~~~^^^^^^^^^^^^^^^^^^^^^^^^^^^^^
  File "/workspace/venv/lib/python3.13/site-packages/django/utils/autoreload.py", line 64, in wrapper
    fn(*args, **kwargs)
    ~~^^^^^^^^^^^^^^^^^
  File "/workspace/venv/lib/python3.13/site-packages/daphne/management/commands/runserver.py", line 109, in inner_run
    self.check(display_num_errors=True)
    ~~~~~~~~~~^^^^^^^^^^^^^^^^^^^^^^^^^
  File "/workspace/venv/lib/python3.13/site-packages/django/core/management/base.py", line 492, in check
    all_issues = checks.run_checks(
        app_configs=app_configs,
    ...<2 lines>...
        databases=databases,
    )
  File "/workspace/venv/lib/python3.13/site-packages/django/core/checks/registry.py", line 89, in run_checks
    new_errors = check(app_configs=app_configs, databases=databases)
  File "/workspace/venv/lib/python3.13/site-packages/django/core/checks/urls.py", line 16, in check_url_config
    return check_resolver(resolver)
  File "/workspace/venv/lib/python3.13/site-packages/django/core/checks/urls.py", line 26, in check_resolver
    return check_method()
  File "/workspace/venv/lib/python3.13/site-packages/django/urls/resolvers.py", line 531, in check
    for pattern in self.url_patterns:
                   ^^^^^^^^^^^^^^^^^
  File "/workspace/venv/lib/python3.13/site-packages/django/utils/functional.py", line 47, in __get__
    res = instance.__dict__[self.name] = self.func(instance)
                                         ~~~~~~~~~^^^^^^^^^^
  File "/workspace/venv/lib/python3.13/site-packages/django/urls/resolvers.py", line 718, in url_patterns
    patterns = getattr(self.urlconf_module, "urlpatterns", self.urlconf_module)
                       ^^^^^^^^^^^^^^^^^^^
  File "/workspace/venv/lib/python3.13/site-packages/django/utils/functional.py", line 47, in __get__
    res = instance.__dict__[self.name] = self.func(instance)
                                         ~~~~~~~~~^^^^^^^^^^
  File "/workspace/venv/lib/python3.13/site-packages/django/urls/resolvers.py", line 711, in urlconf_module
    return import_module(self.urlconf_name)
  File "/usr/lib/python3.13/importlib/__init__.py", line 88, in import_module
    return _bootstrap._gcd_import(name[level:], package, level)
           ~~~~~~~~~~~~~~~~~~~~~~^^^^^^^^^^^^^^^^^^^^^^^^^^^^^^
  File "<frozen importlib._bootstrap>", line 1387, in _gcd_import
  File "<frozen importlib._bootstrap>", line 1360, in _find_and_load
  File "<frozen importlib._bootstrap>", line 1331, in _find_and_load_unlocked
  File "<frozen importlib._bootstrap>", line 935, in _load_unlocked
  File "<frozen importlib._bootstrap_external>", line 1026, in exec_module
  File "<frozen importlib._bootstrap>", line 488, in _call_with_frames_removed
  File "/workspace/noctis_pro/urls.py", line 51, in <module>
    path('dicom-viewer/', include(('dicom_viewer.urls','dicom_viewer'), namespace='dicom_viewer')),
                          ~~~~~~~^^^^^^^^^^^^^^^^^^^^^^^^^^^^^^^^^^^^^^^^^^^^^^^^^^^^^^^^^^^^^^^^
  File "/workspace/venv/lib/python3.13/site-packages/django/urls/conf.py", line 39, in include
    urlconf_module = import_module(urlconf_module)
  File "/usr/lib/python3.13/importlib/__init__.py", line 88, in import_module
    return _bootstrap._gcd_import(name[level:], package, level)
           ~~~~~~~~~~~~~~~~~~~~~~^^^^^^^^^^^^^^^^^^^^^^^^^^^^^^
  File "<frozen importlib._bootstrap>", line 1387, in _gcd_import
  File "<frozen importlib._bootstrap>", line 1360, in _find_and_load
  File "<frozen importlib._bootstrap>", line 1331, in _find_and_load_unlocked
  File "<frozen importlib._bootstrap>", line 935, in _load_unlocked
  File "<frozen importlib._bootstrap_external>", line 1026, in exec_module
  File "<frozen importlib._bootstrap>", line 488, in _call_with_frames_removed
  File "/workspace/dicom_viewer/urls.py", line 2, in <module>
    from . import views
  File "/workspace/dicom_viewer/views.py", line 53, in <module>
    from .reconstruction import (MPRProcessor, MIPProcessor, Bone3DProcessor,
    ...<2 lines>...
                                 get_modality_specific_processor, get_available_reconstruction_types)
  File "/workspace/dicom_viewer/reconstruction.py", line 31, in <module>
    from skimage import measure, morphology, filters
ModuleNotFoundError: No module named 'skimage'
