[32mHTTP GET / 302 [0.01, 127.0.0.1:50982][0m
Watching for file changes with StatReloader
Watching for file changes with StatReloader
Watching for file changes with StatReloader
Watching for file changes with StatReloader
Internal Server Error: /
Traceback (most recent call last):
  File "/home/ubuntu/.local/lib/python3.13/site-packages/django/core/handlers/exception.py", line 55, in inner
    response = get_response(request)
  File "/home/ubuntu/.local/lib/python3.13/site-packages/django/utils/deprecation.py", line 119, in __call__
    response = self.process_request(request)
  File "/workspace/noctis_pro/middleware.py", line 324, in process_request
    if not request.user.is_authenticated:
           ^^^^^^^^^^^^
AttributeError: 'ASGIRequest' object has no attribute 'user'
HTTP GET / 500 [0.00, 127.0.0.1:59660]
Internal Server Error: /
Traceback (most recent call last):
  File "/home/ubuntu/.local/lib/python3.13/site-packages/django/core/handlers/exception.py", line 55, in inner
    response = get_response(request)
  File "/home/ubuntu/.local/lib/python3.13/site-packages/django/utils/deprecation.py", line 119, in __call__
    response = self.process_request(request)
  File "/workspace/noctis_pro/middleware.py", line 324, in process_request
    if not request.user.is_authenticated:
           ^^^^^^^^^^^^
AttributeError: 'ASGIRequest' object has no attribute 'user'
HTTP GET / 500 [0.00, 127.0.0.1:59670]
Internal Server Error: /
Traceback (most recent call last):
  File "/home/ubuntu/.local/lib/python3.13/site-packages/django/core/handlers/exception.py", line 55, in inner
    response = get_response(request)
  File "/home/ubuntu/.local/lib/python3.13/site-packages/django/utils/deprecation.py", line 119, in __call__
    response = self.process_request(request)
  File "/workspace/noctis_pro/middleware.py", line 324, in process_request
    if not request.user.is_authenticated:
           ^^^^^^^^^^^^
AttributeError: 'ASGIRequest' object has no attribute 'user'
HTTP GET / 500 [0.00, 127.0.0.1:40590]
Watching for file changes with StatReloader
Watching for file changes with StatReloader
Watching for file changes with StatReloader
Watching for file changes with StatReloader
Internal Server Error: /admin/
Traceback (most recent call last):
  File "/home/ubuntu/.local/lib/python3.13/site-packages/django/core/handlers/exception.py", line 55, in inner
    response = get_response(request)
  File "/home/ubuntu/.local/lib/python3.13/site-packages/django/utils/deprecation.py", line 119, in __call__
    response = self.process_request(request)
  File "/workspace/noctis_pro/middleware.py", line 324, in process_request
    if not request.user.is_authenticated:
           ^^^^^^^^^^^^
AttributeError: 'ASGIRequest' object has no attribute 'user'
HTTP GET /admin/ 500 [0.00, 127.0.0.1:50314]
/workspace/noctis_pro/settings.py changed, reloading.
Watching for file changes with StatReloader
Watching for file changes with StatReloader
HTTP GET / 302 [0.01, 127.0.0.1:36828]
HTTP GET / 302 [0.00, 127.0.0.1:36836]
HTTP GET /admin/ 302 [0.00, 127.0.0.1:48532]
HTTP GET /admin/ 302 [0.00, 127.0.0.1:38174]
HTTP GET /worklist/ 302 [0.00, 127.0.0.1:38174]
HTTP GET /login/?next=/worklist/ 200 [0.00, 127.0.0.1:38174]
Method Not Allowed (HEAD): /health/simple/
[32mHTTP GET / 302 [0.01, 127.0.0.1:47936][0m
[32mHTTP GET / 302 [0.01, 127.0.0.1:47938][0m
[32mHTTP GET /admin/ 302 [0.00, 127.0.0.1:53108][0m
Watching for file changes with StatReloader
Watching for file changes with StatReloader
Watching for file changes with StatReloader
[32mHTTP GET /admin/ 302 [0.01, 127.0.0.1:49374][0m
/workspace/noctis_pro/urls.py changed, reloading.
Watching for file changes with StatReloader
Watching for file changes with StatReloader
[32mHTTP GET /admin/ 302 [0.01, 127.0.0.1:43932][0m
[32mHTTP GET /admin/ 302 [0.00, 127.0.0.1:33208][0m
[32mHTTP GET /admin/ 302 [0.00, 127.0.0.1:45406][0m
[mHTTP GET /admin/login/ 200 [0.02, 127.0.0.1:45420][0m
[mHTTP GET /admin/login/ 200 [0.01, 127.0.0.1:33958][0m
Forbidden (CSRF cookie not set.): /admin/login/
[31;1mHTTP POST /admin/login/ 403 [0.00, 127.0.0.1:33972][0m
Watching for file changes with StatReloader
Watching for file changes with StatReloader
Watching for file changes with StatReloader
Watching for file changes with StatReloader
Watching for file changes with StatReloader
Watching for file changes with StatReloader
Watching for file changes with StatReloader
[32mHTTP GET / 302 [0.01, 127.0.0.1:51160][0m
[32mHTTP HEAD / 302 [0.01, 127.0.0.1:41790][0m
Watching for file changes with StatReloader
Watching for file changes with StatReloader
[32mHTTP GET / 302 [0.01, 127.0.0.1:55562][0m
[32mHTTP GET / 302 [0.00, 127.0.0.1:55578][0m
[32mHTTP GET / 302 [0.00, 127.0.0.1:44430][0m
[mHTTP GET /login/ 200 [0.01, 127.0.0.1:44430][0m
[mHTTP GET /favicon.ico 204 [0.00, 127.0.0.1:44442][0m
Watching for file changes with StatReloader
Service Unavailable: /health/
HTTP GET /health/ 503 [0.01, 127.0.0.1:44414]
Watching for file changes with StatReloader
Service Unavailable: /health/
HTTP GET /health/ 503 [0.01, 127.0.0.1:51798]
HTTP GET /admin/ 302 [0.01, 127.0.0.1:51802]
HTTP HEAD /admin/ 302 [0.00, 127.0.0.1:51816]
HTTP HEAD /admin/login/ 200 [0.01, 127.0.0.1:56186]
Service Unavailable: /health/
HTTP GET /health/ 503 [0.00, 127.0.0.1:38086]
Watching for file changes with StatReloader
Watching for file changes with StatReloader
Service Unavailable: /health/
Service Unavailable: /health/
Watching for file changes with StatReloader
/workspace/noctis_pro/settings.py changed, reloading.
Watching for file changes with StatReloader
Service Unavailable: /health/
[35;1mHTTP GET /health/ 503 [0.01, 127.0.0.1:49886][0m
[mHTTP GET /login/ 200 [0.00, 127.0.0.1:49902][0m
Watching for file changes with StatReloader
[32mHTTP HEAD / 302 [0.01, 127.0.0.1:44310][0m
[mHTTP HEAD /login/ 200 [0.00, 127.0.0.1:44316][0m
Watching for file changes with StatReloader
[32mHTTP HEAD / 302 [0.01, 127.0.0.1:60146][0m
[mHTTP GET /login/ 200 [0.01, 127.0.0.1:38628][0m
[mHTTP GET /login/ 200 [0.00, 127.0.0.1:38634][0m
[32mHTTP GET /admin/ 302 [0.00, 127.0.0.1:55486][0m
[32mHTTP GET /admin/ 302 [0.00, 127.0.0.1:55500][0m
[32mHTTP GET / 302 [0.00, 127.0.0.1:36434][0m
Watching for file changes with StatReloader
[32mHTTP GET / 302 [0.01, 127.0.0.1:49850][0m
Watching for file changes with StatReloader
[32mHTTP HEAD / 302 [0.01, 127.0.0.1:33936][0m
[mHTTP GET /login/ 200 [0.00, 127.0.0.1:33948][0m
[32mHTTP GET /admin/ 302 [0.00, 127.0.0.1:33956][0m
Service Unavailable: /health/
Service Unavailable: /health/
Service Unavailable: /health/
Watching for file changes with StatReloader
[32mHTTP GET /admin/ 302 [0.01, 127.0.0.1:57668][0m
[32mHTTP GET /admin/ 302 [0.00, 127.0.0.1:57676][0m
Watching for file changes with StatReloader
[32mHTTP GET /admin/ 302 [0.01, 127.0.0.1:50768][0m
[mHTTP GET /admin/login/ 200 [0.01, 127.0.0.1:50774][0m
Service Unavailable: /health/
Service Unavailable: /health/
Service Unavailable: /health/
Watching for file changes with StatReloader
Not Found: /accounts/login/
[33mHTTP HEAD /accounts/login/ 404 [0.01, 127.0.0.1:57854][0m
[32mHTTP HEAD / 302 [0.01, 127.0.0.1:57856][0m
[mHTTP HEAD /login/ 200 [0.00, 127.0.0.1:49242][0m
Forbidden (CSRF cookie not set.): /login/
[31;1mHTTP POST /login/ 403 [0.00, 127.0.0.1:49244][0m
[mHTTP GET /login/ 200 [0.00, 127.0.0.1:35286][0m
[mHTTP GET /login/ 200 [0.00, 127.0.0.1:60748][0m
Internal Server Error: /login/
Traceback (most recent call last):
  File "/workspace/venv/lib/python3.13/site-packages/django_redis/cache.py", line 29, in _decorator
    return method(self, *args, **kwargs)
  File "/workspace/venv/lib/python3.13/site-packages/django_redis/cache.py", line 138, in has_key
    return self.client.has_key(*args, **kwargs)
           ~~~~~~~~~~~~~~~~~~~^^^^^^^^^^^^^^^^^
  File "/workspace/venv/lib/python3.13/site-packages/django_redis/client/default.py", line 740, in has_key
    raise ConnectionInterrupted(connection=client) from e
django_redis.exceptions.ConnectionInterrupted: Redis ConnectionError: Error 111 connecting to 127.0.0.1:6379. Connection refused.

During handling of the above exception, another exception occurred:

Traceback (most recent call last):
  File "/workspace/venv/lib/python3.13/site-packages/asgiref/sync.py", line 489, in thread_handler
    raise exc_info[1]
  File "/workspace/venv/lib/python3.13/site-packages/django/core/handlers/exception.py", line 42, in inner
    response = await get_response(request)
               ^^^^^^^^^^^^^^^^^^^^^^^^^^^
  File "/workspace/venv/lib/python3.13/site-packages/asgiref/sync.py", line 489, in thread_handler
    raise exc_info[1]
  File "/workspace/venv/lib/python3.13/site-packages/django/core/handlers/base.py", line 253, in _get_response_async
    response = await wrapped_callback(
               ^^^^^^^^^^^^^^^^^^^^^^^
        request, *callback_args, **callback_kwargs
        ^^^^^^^^^^^^^^^^^^^^^^^^^^^^^^^^^^^^^^^^^^
    )
    ^
  File "/workspace/venv/lib/python3.13/site-packages/asgiref/sync.py", line 439, in __call__
    ret = await asyncio.shield(exec_coro)
          ^^^^^^^^^^^^^^^^^^^^^^^^^^^^^^^
  File "/workspace/venv/lib/python3.13/site-packages/asgiref/current_thread_executor.py", line 40, in run
    result = self.fn(*self.args, **self.kwargs)
  File "/workspace/venv/lib/python3.13/site-packages/asgiref/sync.py", line 493, in thread_handler
    return func(*args, **kwargs)
  File "/workspace/accounts/views.py", line 34, in login_view
    login(request, user)
    ~~~~~^^^^^^^^^^^^^^^
  File "/workspace/venv/lib/python3.13/site-packages/django/contrib/auth/__init__.py", line 187, in login
    request.session.cycle_key()
    ~~~~~~~~~~~~~~~~~~~~~~~~~^^
  File "/workspace/venv/lib/python3.13/site-packages/django/contrib/sessions/backends/base.py", line 432, in cycle_key
    self.create()
    ~~~~~~~~~~~^^
  File "/workspace/venv/lib/python3.13/site-packages/django/contrib/sessions/backends/cache.py", line 55, in create
    self._session_key = self._get_new_session_key()
                        ~~~~~~~~~~~~~~~~~~~~~~~~~^^
  File "/workspace/venv/lib/python3.13/site-packages/django/contrib/sessions/backends/base.py", line 196, in _get_new_session_key
    if not self.exists(session_key):
           ~~~~~~~~~~~^^^^^^^^^^^^^
  File "/workspace/venv/lib/python3.13/site-packages/django/contrib/sessions/backends/cache.py", line 117, in exists
    bool(session_key) and (self.cache_key_prefix + session_key) in self._cache
                          ^^^^^^^^^^^^^^^^^^^^^^^^^^^^^^^^^^^^^^^^^^^^^^^^^^^^
  File "/workspace/venv/lib/python3.13/site-packages/django/core/cache/backends/base.py", line 301, in __contains__
    return self.has_key(key)
           ~~~~~~~~~~~~^^^^^
  File "/workspace/venv/lib/python3.13/site-packages/django_redis/cache.py", line 36, in _decorator
    raise e.__cause__  # noqa: B904
    ^^^^^^^^^^^^^^^^^
  File "/workspace/venv/lib/python3.13/site-packages/django_redis/client/default.py", line 738, in has_key
    return client.exists(key) == 1
           ~~~~~~~~~~~~~^^^^^
  File "/workspace/venv/lib/python3.13/site-packages/redis/commands/core.py", line 1736, in exists
    return self.execute_command("EXISTS", *names, keys=names)
           ~~~~~~~~~~~~~~~~~~~~^^^^^^^^^^^^^^^^^^^^^^^^^^^^^^
  File "/workspace/venv/lib/python3.13/site-packages/redis/client.py", line 621, in execute_command
    return self._execute_command(*args, **options)
           ~~~~~~~~~~~~~~~~~~~~~^^^^^^^^^^^^^^^^^^
  File "/workspace/venv/lib/python3.13/site-packages/redis/client.py", line 627, in _execute_command
    conn = self.connection or pool.get_connection()
                              ~~~~~~~~~~~~~~~~~~~^^
  File "/workspace/venv/lib/python3.13/site-packages/redis/utils.py", line 195, in wrapper
    return func(*args, **kwargs)
  File "/workspace/venv/lib/python3.13/site-packages/redis/connection.py", line 1533, in get_connection
    connection.connect()
    ~~~~~~~~~~~~~~~~~~^^
  File "/workspace/venv/lib/python3.13/site-packages/redis/connection.py", line 380, in connect
    self.connect_check_health(check_health=True)
    ~~~~~~~~~~~~~~~~~~~~~~~~~^^^^^^^^^^^^^^^^^^^
  File "/workspace/venv/lib/python3.13/site-packages/redis/connection.py", line 397, in connect_check_health
    raise ConnectionError(self._error_message(e))
redis.exceptions.ConnectionError: Error 111 connecting to 127.0.0.1:6379. Connection refused.
[35;1mHTTP POST /login/ 500 [0.21, 127.0.0.1:60762][0m
Watching for file changes with StatReloader
[mHTTP GET /login/ 200 [0.01, 127.0.0.1:50332][0m
Watching for file changes with StatReloader
[mHTTP HEAD /login/ 200 [0.00, 127.0.0.1:43880][0m
[mHTTP GET /login/ 200 [0.00, 127.0.0.1:47024][0m
Internal Server Error: /login/
Traceback (most recent call last):
  File "/workspace/venv/lib/python3.13/site-packages/django_redis/cache.py", line 29, in _decorator
    return method(self, *args, **kwargs)
  File "/workspace/venv/lib/python3.13/site-packages/django_redis/cache.py", line 138, in has_key
    return self.client.has_key(*args, **kwargs)
           ~~~~~~~~~~~~~~~~~~~^^^^^^^^^^^^^^^^^
  File "/workspace/venv/lib/python3.13/site-packages/django_redis/client/default.py", line 740, in has_key
    raise ConnectionInterrupted(connection=client) from e
django_redis.exceptions.ConnectionInterrupted: Redis ConnectionError: Error 111 connecting to 127.0.0.1:6379. Connection refused.

During handling of the above exception, another exception occurred:

Traceback (most recent call last):
  File "/workspace/venv/lib/python3.13/site-packages/asgiref/sync.py", line 489, in thread_handler
    raise exc_info[1]
  File "/workspace/venv/lib/python3.13/site-packages/django/core/handlers/exception.py", line 42, in inner
    response = await get_response(request)
               ^^^^^^^^^^^^^^^^^^^^^^^^^^^
  File "/workspace/venv/lib/python3.13/site-packages/asgiref/sync.py", line 489, in thread_handler
    raise exc_info[1]
  File "/workspace/venv/lib/python3.13/site-packages/django/core/handlers/base.py", line 253, in _get_response_async
    response = await wrapped_callback(
               ^^^^^^^^^^^^^^^^^^^^^^^
        request, *callback_args, **callback_kwargs
        ^^^^^^^^^^^^^^^^^^^^^^^^^^^^^^^^^^^^^^^^^^
    )
    ^
  File "/workspace/venv/lib/python3.13/site-packages/asgiref/sync.py", line 439, in __call__
    ret = await asyncio.shield(exec_coro)
          ^^^^^^^^^^^^^^^^^^^^^^^^^^^^^^^
  File "/workspace/venv/lib/python3.13/site-packages/asgiref/current_thread_executor.py", line 40, in run
    result = self.fn(*self.args, **self.kwargs)
  File "/workspace/venv/lib/python3.13/site-packages/asgiref/sync.py", line 493, in thread_handler
    return func(*args, **kwargs)
  File "/workspace/accounts/views.py", line 34, in login_view
    login(request, user)
    ~~~~~^^^^^^^^^^^^^^^
  File "/workspace/venv/lib/python3.13/site-packages/django/contrib/auth/__init__.py", line 187, in login
    request.session.cycle_key()
    ~~~~~~~~~~~~~~~~~~~~~~~~~^^
  File "/workspace/venv/lib/python3.13/site-packages/django/contrib/sessions/backends/base.py", line 432, in cycle_key
    self.create()
    ~~~~~~~~~~~^^
  File "/workspace/venv/lib/python3.13/site-packages/django/contrib/sessions/backends/cache.py", line 55, in create
    self._session_key = self._get_new_session_key()
                        ~~~~~~~~~~~~~~~~~~~~~~~~~^^
  File "/workspace/venv/lib/python3.13/site-packages/django/contrib/sessions/backends/base.py", line 196, in _get_new_session_key
    if not self.exists(session_key):
           ~~~~~~~~~~~^^^^^^^^^^^^^
  File "/workspace/venv/lib/python3.13/site-packages/django/contrib/sessions/backends/cache.py", line 117, in exists
    bool(session_key) and (self.cache_key_prefix + session_key) in self._cache
                          ^^^^^^^^^^^^^^^^^^^^^^^^^^^^^^^^^^^^^^^^^^^^^^^^^^^^
  File "/workspace/venv/lib/python3.13/site-packages/django/core/cache/backends/base.py", line 301, in __contains__
    return self.has_key(key)
           ~~~~~~~~~~~~^^^^^
  File "/workspace/venv/lib/python3.13/site-packages/django_redis/cache.py", line 36, in _decorator
    raise e.__cause__  # noqa: B904
    ^^^^^^^^^^^^^^^^^
  File "/workspace/venv/lib/python3.13/site-packages/django_redis/client/default.py", line 738, in has_key
    return client.exists(key) == 1
           ~~~~~~~~~~~~~^^^^^
  File "/workspace/venv/lib/python3.13/site-packages/redis/commands/core.py", line 1736, in exists
    return self.execute_command("EXISTS", *names, keys=names)
           ~~~~~~~~~~~~~~~~~~~~^^^^^^^^^^^^^^^^^^^^^^^^^^^^^^
  File "/workspace/venv/lib/python3.13/site-packages/redis/client.py", line 621, in execute_command
    return self._execute_command(*args, **options)
           ~~~~~~~~~~~~~~~~~~~~~^^^^^^^^^^^^^^^^^^
  File "/workspace/venv/lib/python3.13/site-packages/redis/client.py", line 627, in _execute_command
    conn = self.connection or pool.get_connection()
                              ~~~~~~~~~~~~~~~~~~~^^
  File "/workspace/venv/lib/python3.13/site-packages/redis/utils.py", line 195, in wrapper
    return func(*args, **kwargs)
  File "/workspace/venv/lib/python3.13/site-packages/redis/connection.py", line 1533, in get_connection
    connection.connect()
    ~~~~~~~~~~~~~~~~~~^^
  File "/workspace/venv/lib/python3.13/site-packages/redis/connection.py", line 380, in connect
    self.connect_check_health(check_health=True)
    ~~~~~~~~~~~~~~~~~~~~~~~~~^^^^^^^^^^^^^^^^^^^
  File "/workspace/venv/lib/python3.13/site-packages/redis/connection.py", line 397, in connect_check_health
    raise ConnectionError(self._error_message(e))
redis.exceptions.ConnectionError: Error 111 connecting to 127.0.0.1:6379. Connection refused.
[35;1mHTTP POST /login/ 500 [0.23, 127.0.0.1:47028][0m
Watching for file changes with StatReloader
[mHTTP HEAD /login/ 200 [0.01, 127.0.0.1:43686][0m
[mHTTP GET /login/ 200 [0.00, 127.0.0.1:43700][0m
Internal Server Error: /login/
Traceback (most recent call last):
  File "/workspace/venv/lib/python3.13/site-packages/django_redis/cache.py", line 29, in _decorator
    return method(self, *args, **kwargs)
  File "/workspace/venv/lib/python3.13/site-packages/django_redis/cache.py", line 138, in has_key
    return self.client.has_key(*args, **kwargs)
           ~~~~~~~~~~~~~~~~~~~^^^^^^^^^^^^^^^^^
  File "/workspace/venv/lib/python3.13/site-packages/django_redis/client/default.py", line 740, in has_key
    raise ConnectionInterrupted(connection=client) from e
django_redis.exceptions.ConnectionInterrupted: Redis ConnectionError: Error 111 connecting to 127.0.0.1:6379. Connection refused.

During handling of the above exception, another exception occurred:

Traceback (most recent call last):
  File "/workspace/venv/lib/python3.13/site-packages/asgiref/sync.py", line 489, in thread_handler
    raise exc_info[1]
  File "/workspace/venv/lib/python3.13/site-packages/django/core/handlers/exception.py", line 42, in inner
    response = await get_response(request)
               ^^^^^^^^^^^^^^^^^^^^^^^^^^^
  File "/workspace/venv/lib/python3.13/site-packages/asgiref/sync.py", line 489, in thread_handler
    raise exc_info[1]
  File "/workspace/venv/lib/python3.13/site-packages/django/core/handlers/base.py", line 253, in _get_response_async
    response = await wrapped_callback(
               ^^^^^^^^^^^^^^^^^^^^^^^
        request, *callback_args, **callback_kwargs
        ^^^^^^^^^^^^^^^^^^^^^^^^^^^^^^^^^^^^^^^^^^
    )
    ^
  File "/workspace/venv/lib/python3.13/site-packages/asgiref/sync.py", line 439, in __call__
    ret = await asyncio.shield(exec_coro)
          ^^^^^^^^^^^^^^^^^^^^^^^^^^^^^^^
  File "/workspace/venv/lib/python3.13/site-packages/asgiref/current_thread_executor.py", line 40, in run
    result = self.fn(*self.args, **self.kwargs)
  File "/workspace/venv/lib/python3.13/site-packages/asgiref/sync.py", line 493, in thread_handler
    return func(*args, **kwargs)
  File "/workspace/accounts/views.py", line 34, in login_view
    login(request, user)
    ~~~~~^^^^^^^^^^^^^^^
  File "/workspace/venv/lib/python3.13/site-packages/django/contrib/auth/__init__.py", line 187, in login
    request.session.cycle_key()
    ~~~~~~~~~~~~~~~~~~~~~~~~~^^
  File "/workspace/venv/lib/python3.13/site-packages/django/contrib/sessions/backends/base.py", line 432, in cycle_key
    self.create()
    ~~~~~~~~~~~^^
  File "/workspace/venv/lib/python3.13/site-packages/django/contrib/sessions/backends/cache.py", line 55, in create
    self._session_key = self._get_new_session_key()
                        ~~~~~~~~~~~~~~~~~~~~~~~~~^^
  File "/workspace/venv/lib/python3.13/site-packages/django/contrib/sessions/backends/base.py", line 196, in _get_new_session_key
    if not self.exists(session_key):
           ~~~~~~~~~~~^^^^^^^^^^^^^
  File "/workspace/venv/lib/python3.13/site-packages/django/contrib/sessions/backends/cache.py", line 117, in exists
    bool(session_key) and (self.cache_key_prefix + session_key) in self._cache
                          ^^^^^^^^^^^^^^^^^^^^^^^^^^^^^^^^^^^^^^^^^^^^^^^^^^^^
  File "/workspace/venv/lib/python3.13/site-packages/django/core/cache/backends/base.py", line 301, in __contains__
    return self.has_key(key)
           ~~~~~~~~~~~~^^^^^
  File "/workspace/venv/lib/python3.13/site-packages/django_redis/cache.py", line 36, in _decorator
    raise e.__cause__  # noqa: B904
    ^^^^^^^^^^^^^^^^^
  File "/workspace/venv/lib/python3.13/site-packages/django_redis/client/default.py", line 738, in has_key
    return client.exists(key) == 1
           ~~~~~~~~~~~~~^^^^^
  File "/workspace/venv/lib/python3.13/site-packages/redis/commands/core.py", line 1736, in exists
    return self.execute_command("EXISTS", *names, keys=names)
           ~~~~~~~~~~~~~~~~~~~~^^^^^^^^^^^^^^^^^^^^^^^^^^^^^^
  File "/workspace/venv/lib/python3.13/site-packages/redis/client.py", line 621, in execute_command
    return self._execute_command(*args, **options)
           ~~~~~~~~~~~~~~~~~~~~~^^^^^^^^^^^^^^^^^^
  File "/workspace/venv/lib/python3.13/site-packages/redis/client.py", line 627, in _execute_command
    conn = self.connection or pool.get_connection()
                              ~~~~~~~~~~~~~~~~~~~^^
  File "/workspace/venv/lib/python3.13/site-packages/redis/utils.py", line 195, in wrapper
    return func(*args, **kwargs)
  File "/workspace/venv/lib/python3.13/site-packages/redis/connection.py", line 1533, in get_connection
    connection.connect()
    ~~~~~~~~~~~~~~~~~~^^
  File "/workspace/venv/lib/python3.13/site-packages/redis/connection.py", line 380, in connect
    self.connect_check_health(check_health=True)
    ~~~~~~~~~~~~~~~~~~~~~~~~~^^^^^^^^^^^^^^^^^^^
  File "/workspace/venv/lib/python3.13/site-packages/redis/connection.py", line 397, in connect_check_health
    raise ConnectionError(self._error_message(e))
redis.exceptions.ConnectionError: Error 111 connecting to 127.0.0.1:6379. Connection refused.
[35;1mHTTP POST /login/ 500 [0.22, 127.0.0.1:43710][0m
Watching for file changes with StatReloader
[mHTTP HEAD /login/ 200 [0.01, 127.0.0.1:57606][0m
[mHTTP GET /login/ 200 [0.00, 127.0.0.1:57622][0m
Internal Server Error: /login/
Traceback (most recent call last):
  File "/workspace/venv/lib/python3.13/site-packages/asgiref/sync.py", line 489, in thread_handler
    raise exc_info[1]
  File "/workspace/venv/lib/python3.13/site-packages/django/core/handlers/exception.py", line 42, in inner
    response = await get_response(request)
               ^^^^^^^^^^^^^^^^^^^^^^^^^^^
  File "/workspace/venv/lib/python3.13/site-packages/django/utils/deprecation.py", line 138, in __acall__
    response = await sync_to_async(
               ^^^^^^^^^^^^^^^^^^^^
    ...<2 lines>...
    )(request, response)
    ^^^^^^^^^^^^^^^^^^^^
  File "/workspace/venv/lib/python3.13/site-packages/asgiref/sync.py", line 439, in __call__
    ret = await asyncio.shield(exec_coro)
          ^^^^^^^^^^^^^^^^^^^^^^^^^^^^^^^
  File "/workspace/venv/lib/python3.13/site-packages/asgiref/current_thread_executor.py", line 40, in run
    result = self.fn(*self.args, **self.kwargs)
  File "/workspace/venv/lib/python3.13/site-packages/asgiref/sync.py", line 493, in thread_handler
    return func(*args, **kwargs)
  File "/workspace/noctis_pro/middleware.py", line 423, in process_response
    <div>Your session will expire in <span id="countdown">${timeLeft}</span> seconds due to inactivity.</div>
                                                            ^^^^^^^^
NameError: name 'timeLeft' is not defined. Did you mean: 'timedelta'?
[35;1mHTTP POST /login/ 500 [0.23, 127.0.0.1:57628][0m
Watching for file changes with StatReloader
[mHTTP HEAD /login/ 200 [0.01, 127.0.0.1:45526][0m
[mHTTP GET /login/ 200 [0.00, 127.0.0.1:45532][0m
Internal Server Error: /login/
Traceback (most recent call last):
  File "/workspace/venv/lib/python3.13/site-packages/asgiref/sync.py", line 489, in thread_handler
    raise exc_info[1]
  File "/workspace/venv/lib/python3.13/site-packages/django/core/handlers/exception.py", line 42, in inner
    response = await get_response(request)
               ^^^^^^^^^^^^^^^^^^^^^^^^^^^
  File "/workspace/venv/lib/python3.13/site-packages/django/utils/deprecation.py", line 138, in __acall__
    response = await sync_to_async(
               ^^^^^^^^^^^^^^^^^^^^
    ...<2 lines>...
    )(request, response)
    ^^^^^^^^^^^^^^^^^^^^
  File "/workspace/venv/lib/python3.13/site-packages/asgiref/sync.py", line 439, in __call__
    ret = await asyncio.shield(exec_coro)
          ^^^^^^^^^^^^^^^^^^^^^^^^^^^^^^^
  File "/workspace/venv/lib/python3.13/site-packages/asgiref/current_thread_executor.py", line 40, in run
    result = self.fn(*self.args, **self.kwargs)
  File "/workspace/venv/lib/python3.13/site-packages/asgiref/sync.py", line 493, in thread_handler
    return func(*args, **kwargs)
  File "/workspace/noctis_pro/middleware.py", line 423, in process_response
    <div>Your session will expire in <span id="countdown">${timeLeft}</span> seconds due to inactivity.</div>
                                                            ^^^^^^^^
NameError: name 'timeLeft' is not defined. Did you mean: 'timedelta'?
[35;1mHTTP POST /login/ 500 [0.23, 127.0.0.1:45544][0m
[mHTTP GET /login/ 200 [0.00, 127.0.0.1:54228][0m
Internal Server Error: /login/
Traceback (most recent call last):
  File "/workspace/venv/lib/python3.13/site-packages/asgiref/sync.py", line 489, in thread_handler
    raise exc_info[1]
  File "/workspace/venv/lib/python3.13/site-packages/django/core/handlers/exception.py", line 42, in inner
    response = await get_response(request)
               ^^^^^^^^^^^^^^^^^^^^^^^^^^^
  File "/workspace/venv/lib/python3.13/site-packages/django/utils/deprecation.py", line 138, in __acall__
    response = await sync_to_async(
               ^^^^^^^^^^^^^^^^^^^^
    ...<2 lines>...
    )(request, response)
    ^^^^^^^^^^^^^^^^^^^^
  File "/workspace/venv/lib/python3.13/site-packages/asgiref/sync.py", line 439, in __call__
    ret = await asyncio.shield(exec_coro)
          ^^^^^^^^^^^^^^^^^^^^^^^^^^^^^^^
  File "/workspace/venv/lib/python3.13/site-packages/asgiref/current_thread_executor.py", line 40, in run
    result = self.fn(*self.args, **self.kwargs)
  File "/workspace/venv/lib/python3.13/site-packages/asgiref/sync.py", line 493, in thread_handler
    return func(*args, **kwargs)
  File "/workspace/noctis_pro/middleware.py", line 423, in process_response
    <div>Your session will expire in <span id="countdown">${timeLeft}</span> seconds due to inactivity.</div>
                                                            ^^^^^^^^
NameError: name 'timeLeft' is not defined. Did you mean: 'timedelta'?
[35;1mHTTP POST /login/ 500 [0.22, 127.0.0.1:54236][0m
/workspace/noctis_pro/middleware.py changed, reloading.
Watching for file changes with StatReloader
Watching for file changes with StatReloader
[mHTTP GET /login/ 200 [0.01, 127.0.0.1:53654][0m
[32mHTTP POST /login/ 302 [0.22, 127.0.0.1:53656][0m
Forbidden (CSRF token missing.): /worklist/
[31;1mHTTP POST /worklist/ 403 [0.01, 127.0.0.1:53656][0m
Forbidden (CSRF cookie not set.): /login/
[31;1mHTTP POST /login/ 403 [0.00, 127.0.0.1:53672][0m
[mHTTP GET /login/ 200 [0.00, 127.0.0.1:53674][0m
Watching for file changes with StatReloader
[32mHTTP GET / 302 [0.01, 127.0.0.1:59564][0m
[32mHTTP GET /admin/ 302 [0.00, 127.0.0.1:44214][0m
[mHTTP GET /login/ 200 [0.00, 127.0.0.1:44224][0m
[32mHTTP HEAD / 302 [0.01, 127.0.0.1:44832][0m
[mHTTP HEAD /login/ 200 [0.01, 127.0.0.1:47160][0m
[32mHTTP HEAD /worklist/upload/ 302 [0.00, 127.0.0.1:47168][0m
Watching for file changes with StatReloader
