Thu Aug 28 03:48:00 PM UTC 2025: Starting NoctisPro Complete System...
2025-08-28 15:48:00: Loading production environment...
2025-08-28 15:48:00: Loading ngrok environment...
2025-08-28 15:48:00: Activating virtual environment...
/workspace/start_complete_system.sh: line 65: venv/bin/activate: No such file or directory
Thu Aug 28 04:56:47 PM UTC 2025: Starting NoctisPro Complete System...
2025-08-28 16:56:47: Loading production environment...
2025-08-28 16:56:47: Loading ngrok environment...
2025-08-28 16:56:47: Activating virtual environment...
/workspace/start_complete_system.sh: line 65: venv/bin/activate: No such file or directory
Thu Aug 28 04:57:09 PM UTC 2025: Stopping NoctisPro Complete System...
2025-08-28 16:57:09: No PID file found, attempting to find and stop processes...
2025-08-28 16:57:09: Ngrok is not running or PID invalid
2025-08-28 16:57:09: DICOM Receiver is not running or PID invalid
2025-08-28 16:57:09: Django is not running or PID invalid
2025-08-28 16:57:09: ==================== SHUTDOWN COMPLETE ====================
2025-08-28 16:57:09: All NoctisPro services have been stopped
2025-08-28 16:57:09: ==============================================================
Thu Aug 28 04:57:17 PM UTC 2025: Starting NoctisPro Complete System...
2025-08-28 16:57:17: Loading production environment...
2025-08-28 16:57:17: Loading ngrok environment...
2025-08-28 16:57:17: Activating virtual environment...
./start_complete_system.sh: line 65: venv/bin/activate: No such file or directory
Thu Aug 28 05:01:14 PM UTC 2025: Starting NoctisPro Complete System...
2025-08-28 17:01:14: Loading production environment...
2025-08-28 17:01:14: Loading ngrok environment...
2025-08-28 17:01:14: Activating virtual environment...
2025-08-28 17:01:14: Checking database connectivity...
Database connection successful
2025-08-28 17:01:14: Starting Django application...
2025-08-28 17:01:14: Django started with PID 5784
2025-08-28 17:01:14: Waiting for service at http://localhost:8000...
2025-08-28 17:01:14: Attempt 1/30: Service not ready, waiting...
Exception in thread django-main-thread:
Traceback (most recent call last):
  File "/usr/lib/python3.13/threading.py", line 1041, in _bootstrap_inner
    self.run()
    ~~~~~~~~^^
  File "/usr/lib/python3.13/threading.py", line 992, in run
    self._target(*self._args, **self._kwargs)
    ~~~~~~~~~~~~^^^^^^^^^^^^^^^^^^^^^^^^^^^^^
  File "/workspace/venv/lib/python3.13/site-packages/django/utils/autoreload.py", line 64, in wrapper
    fn(*args, **kwargs)
    ~~^^^^^^^^^^^^^^^^^
  File "/workspace/venv/lib/python3.13/site-packages/daphne/management/commands/runserver.py", line 109, in inner_run
    self.check(display_num_errors=True)
    ~~~~~~~~~~^^^^^^^^^^^^^^^^^^^^^^^^^
  File "/workspace/venv/lib/python3.13/site-packages/django/core/management/base.py", line 492, in check
    all_issues = checks.run_checks(
        app_configs=app_configs,
    ...<2 lines>...
        databases=databases,
    )
  File "/workspace/venv/lib/python3.13/site-packages/django/core/checks/registry.py", line 89, in run_checks
    new_errors = check(app_configs=app_configs, databases=databases)
  File "/workspace/venv/lib/python3.13/site-packages/django/core/checks/urls.py", line 16, in check_url_config
    return check_resolver(resolver)
  File "/workspace/venv/lib/python3.13/site-packages/django/core/checks/urls.py", line 26, in check_resolver
    return check_method()
  File "/workspace/venv/lib/python3.13/site-packages/django/urls/resolvers.py", line 531, in check
    for pattern in self.url_patterns:
                   ^^^^^^^^^^^^^^^^^
  File "/workspace/venv/lib/python3.13/site-packages/django/utils/functional.py", line 47, in __get__
    res = instance.__dict__[self.name] = self.func(instance)
                                         ~~~~~~~~~^^^^^^^^^^
  File "/workspace/venv/lib/python3.13/site-packages/django/urls/resolvers.py", line 718, in url_patterns
    patterns = getattr(self.urlconf_module, "urlpatterns", self.urlconf_module)
                       ^^^^^^^^^^^^^^^^^^^
  File "/workspace/venv/lib/python3.13/site-packages/django/utils/functional.py", line 47, in __get__
    res = instance.__dict__[self.name] = self.func(instance)
                                         ~~~~~~~~~^^^^^^^^^^
  File "/workspace/venv/lib/python3.13/site-packages/django/urls/resolvers.py", line 711, in urlconf_module
    return import_module(self.urlconf_name)
  File "/usr/lib/python3.13/importlib/__init__.py", line 88, in import_module
    return _bootstrap._gcd_import(name[level:], package, level)
           ~~~~~~~~~~~~~~~~~~~~~~^^^^^^^^^^^^^^^^^^^^^^^^^^^^^^
  File "<frozen importlib._bootstrap>", line 1387, in _gcd_import
  File "<frozen importlib._bootstrap>", line 1360, in _find_and_load
  File "<frozen importlib._bootstrap>", line 1331, in _find_and_load_unlocked
  File "<frozen importlib._bootstrap>", line 935, in _load_unlocked
  File "<frozen importlib._bootstrap_external>", line 1026, in exec_module
  File "<frozen importlib._bootstrap>", line 488, in _call_with_frames_removed
  File "/workspace/noctis_pro/urls.py", line 47, in <module>
    path('dicom-viewer/', include(('dicom_viewer.urls','dicom_viewer'), namespace='dicom_viewer')),  # single namespaced include
                          ~~~~~~~^^^^^^^^^^^^^^^^^^^^^^^^^^^^^^^^^^^^^^^^^^^^^^^^^^^^^^^^^^^^^^^^
  File "/workspace/venv/lib/python3.13/site-packages/django/urls/conf.py", line 39, in include
    urlconf_module = import_module(urlconf_module)
  File "/usr/lib/python3.13/importlib/__init__.py", line 88, in import_module
    return _bootstrap._gcd_import(name[level:], package, level)
           ~~~~~~~~~~~~~~~~~~~~~~^^^^^^^^^^^^^^^^^^^^^^^^^^^^^^
  File "<frozen importlib._bootstrap>", line 1387, in _gcd_import
  File "<frozen importlib._bootstrap>", line 1360, in _find_and_load
  File "<frozen importlib._bootstrap>", line 1331, in _find_and_load_unlocked
  File "<frozen importlib._bootstrap>", line 935, in _load_unlocked
  File "<frozen importlib._bootstrap_external>", line 1026, in exec_module
  File "<frozen importlib._bootstrap>", line 488, in _call_with_frames_removed
  File "/workspace/dicom_viewer/urls.py", line 2, in <module>
    from . import views
  File "/workspace/dicom_viewer/views.py", line 2376
    pos = getattr(ds, 'ImagePositionPatient', None)
    ^^^
SyntaxError: expected 'except' or 'finally' block
2025-08-28 17:01:16: Attempt 2/30: Service not ready, waiting...
2025-08-28 17:01:18: Attempt 3/30: Service not ready, waiting...
2025-08-28 17:01:20: Attempt 4/30: Service not ready, waiting...
2025-08-28 17:01:22: Attempt 5/30: Service not ready, waiting...
2025-08-28 17:01:24: Attempt 6/30: Service not ready, waiting...
2025-08-28 17:01:26: Attempt 7/30: Service not ready, waiting...
2025-08-28 17:01:28: Attempt 8/30: Service not ready, waiting...
2025-08-28 17:01:31: Attempt 9/30: Service not ready, waiting...
2025-08-28 17:01:33: Attempt 10/30: Service not ready, waiting...
2025-08-28 17:01:35: Attempt 11/30: Service not ready, waiting...
2025-08-28 17:01:37: Attempt 12/30: Service not ready, waiting...
2025-08-28 17:01:39: Attempt 13/30: Service not ready, waiting...
2025-08-28 17:01:41: Attempt 14/30: Service not ready, waiting...
2025-08-28 17:01:43: Attempt 15/30: Service not ready, waiting...
2025-08-28 17:01:45: Attempt 16/30: Service not ready, waiting...
2025-08-28 17:01:47: Attempt 17/30: Service not ready, waiting...
2025-08-28 17:01:49: Attempt 18/30: Service not ready, waiting...
2025-08-28 17:01:51: Attempt 19/30: Service not ready, waiting...
2025-08-28 17:01:53: Attempt 20/30: Service not ready, waiting...
2025-08-28 17:01:55: Attempt 21/30: Service not ready, waiting...
Thu Aug 28 05:01:56 PM UTC 2025: Stopping NoctisPro Complete System...
2025-08-28 17:01:56: No PID file found, attempting to find and stop processes...
2025-08-28 17:01:56: Ngrok is not running or PID invalid
2025-08-28 17:01:56: DICOM Receiver is not running or PID invalid
2025-08-28 17:01:56: Stopping Django (PID: 5784)...
2025-08-28 17:01:57: Attempt 22/30: Service not ready, waiting...
2025-08-28 17:01:57: Django stopped gracefully
2025-08-28 17:01:57: ==================== SHUTDOWN COMPLETE ====================
2025-08-28 17:01:57: All NoctisPro services have been stopped
2025-08-28 17:01:57: ==============================================================
2025-08-28 17:01:59: Attempt 23/30: Service not ready, waiting...
2025-08-28 17:02:01: Attempt 24/30: Service not ready, waiting...
2025-08-28 17:02:03: Attempt 25/30: Service not ready, waiting...
Thu Aug 28 05:02:03 PM UTC 2025: Starting NoctisPro Complete System...
2025-08-28 17:02:03: Loading production environment...
2025-08-28 17:02:03: Loading ngrok environment...
2025-08-28 17:02:03: Activating virtual environment...
2025-08-28 17:02:03: Checking database connectivity...
Database connection successful
2025-08-28 17:02:03: Starting Django application...
2025-08-28 17:02:03: Django started with PID 6162
2025-08-28 17:02:03: Waiting for service at http://localhost:8000...
2025-08-28 17:02:03: Attempt 1/30: Service not ready, waiting...
Exception in thread django-main-thread:
Traceback (most recent call last):
  File "/usr/lib/python3.13/threading.py", line 1041, in _bootstrap_inner
    self.run()
    ~~~~~~~~^^
  File "/usr/lib/python3.13/threading.py", line 992, in run
    self._target(*self._args, **self._kwargs)
    ~~~~~~~~~~~~^^^^^^^^^^^^^^^^^^^^^^^^^^^^^
  File "/workspace/venv/lib/python3.13/site-packages/django/utils/autoreload.py", line 64, in wrapper
    fn(*args, **kwargs)
    ~~^^^^^^^^^^^^^^^^^
  File "/workspace/venv/lib/python3.13/site-packages/daphne/management/commands/runserver.py", line 109, in inner_run
    self.check(display_num_errors=True)
    ~~~~~~~~~~^^^^^^^^^^^^^^^^^^^^^^^^^
  File "/workspace/venv/lib/python3.13/site-packages/django/core/management/base.py", line 492, in check
    all_issues = checks.run_checks(
        app_configs=app_configs,
    ...<2 lines>...
        databases=databases,
    )
  File "/workspace/venv/lib/python3.13/site-packages/django/core/checks/registry.py", line 89, in run_checks
    new_errors = check(app_configs=app_configs, databases=databases)
  File "/workspace/venv/lib/python3.13/site-packages/django/core/checks/urls.py", line 16, in check_url_config
    return check_resolver(resolver)
  File "/workspace/venv/lib/python3.13/site-packages/django/core/checks/urls.py", line 26, in check_resolver
    return check_method()
  File "/workspace/venv/lib/python3.13/site-packages/django/urls/resolvers.py", line 531, in check
    for pattern in self.url_patterns:
                   ^^^^^^^^^^^^^^^^^
  File "/workspace/venv/lib/python3.13/site-packages/django/utils/functional.py", line 47, in __get__
    res = instance.__dict__[self.name] = self.func(instance)
                                         ~~~~~~~~~^^^^^^^^^^
  File "/workspace/venv/lib/python3.13/site-packages/django/urls/resolvers.py", line 718, in url_patterns
    patterns = getattr(self.urlconf_module, "urlpatterns", self.urlconf_module)
                       ^^^^^^^^^^^^^^^^^^^
  File "/workspace/venv/lib/python3.13/site-packages/django/utils/functional.py", line 47, in __get__
    res = instance.__dict__[self.name] = self.func(instance)
                                         ~~~~~~~~~^^^^^^^^^^
  File "/workspace/venv/lib/python3.13/site-packages/django/urls/resolvers.py", line 711, in urlconf_module
    return import_module(self.urlconf_name)
  File "/usr/lib/python3.13/importlib/__init__.py", line 88, in import_module
    return _bootstrap._gcd_import(name[level:], package, level)
           ~~~~~~~~~~~~~~~~~~~~~~^^^^^^^^^^^^^^^^^^^^^^^^^^^^^^
  File "<frozen importlib._bootstrap>", line 1387, in _gcd_import
  File "<frozen importlib._bootstrap>", line 1360, in _find_and_load
  File "<frozen importlib._bootstrap>", line 1331, in _find_and_load_unlocked
  File "<frozen importlib._bootstrap>", line 935, in _load_unlocked
  File "<frozen importlib._bootstrap_external>", line 1026, in exec_module
  File "<frozen importlib._bootstrap>", line 488, in _call_with_frames_removed
  File "/workspace/noctis_pro/urls.py", line 47, in <module>
    path('dicom-viewer/', include(('dicom_viewer.urls','dicom_viewer'), namespace='dicom_viewer')),  # single namespaced include
                          ~~~~~~~^^^^^^^^^^^^^^^^^^^^^^^^^^^^^^^^^^^^^^^^^^^^^^^^^^^^^^^^^^^^^^^^
  File "/workspace/venv/lib/python3.13/site-packages/django/urls/conf.py", line 39, in include
    urlconf_module = import_module(urlconf_module)
  File "/usr/lib/python3.13/importlib/__init__.py", line 88, in import_module
    return _bootstrap._gcd_import(name[level:], package, level)
           ~~~~~~~~~~~~~~~~~~~~~~^^^^^^^^^^^^^^^^^^^^^^^^^^^^^^
  File "<frozen importlib._bootstrap>", line 1387, in _gcd_import
  File "<frozen importlib._bootstrap>", line 1360, in _find_and_load
  File "<frozen importlib._bootstrap>", line 1331, in _find_and_load_unlocked
  File "<frozen importlib._bootstrap>", line 935, in _load_unlocked
  File "<frozen importlib._bootstrap_external>", line 1026, in exec_module
  File "<frozen importlib._bootstrap>", line 488, in _call_with_frames_removed
  File "/workspace/dicom_viewer/urls.py", line 2, in <module>
    from . import views
  File "/workspace/dicom_viewer/views.py", line 2376
    pos = getattr(ds, 'ImagePositionPatient', None)
    ^^^
SyntaxError: expected 'except' or 'finally' block
2025-08-28 17:02:05: Attempt 26/30: Service not ready, waiting...
2025-08-28 17:02:05: Attempt 2/30: Service not ready, waiting...
2025-08-28 17:02:07: Attempt 27/30: Service not ready, waiting...
2025-08-28 17:02:07: Attempt 3/30: Service not ready, waiting...
2025-08-28 17:02:09: Attempt 28/30: Service not ready, waiting...
2025-08-28 17:02:09: Attempt 4/30: Service not ready, waiting...
2025-08-28 17:02:11: Attempt 29/30: Service not ready, waiting...
2025-08-28 17:02:11: Attempt 5/30: Service not ready, waiting...
2025-08-28 17:02:13: Attempt 30/30: Service not ready, waiting...
2025-08-28 17:02:13: Attempt 6/30: Service not ready, waiting...
2025-08-28 17:02:15: Service failed to start after 30 attempts
2025-08-28 17:02:15: Django failed to start properly
2025-08-28 17:02:15: Attempt 7/30: Service not ready, waiting...
2025-08-28 17:02:17: Attempt 8/30: Service not ready, waiting...
2025-08-28 17:02:19: Attempt 9/30: Service not ready, waiting...
2025-08-28 17:02:21: Attempt 10/30: Service not ready, waiting...
2025-08-28 17:02:23: Attempt 11/30: Service not ready, waiting...
2025-08-28 17:02:25: Attempt 12/30: Service not ready, waiting...
2025-08-28 17:02:27: Attempt 13/30: Service not ready, waiting...
2025-08-28 17:02:29: Attempt 14/30: Service not ready, waiting...
2025-08-28 17:02:31: Attempt 15/30: Service not ready, waiting...
2025-08-28 17:02:33: Attempt 16/30: Service not ready, waiting...
2025-08-28 17:02:35: Attempt 17/30: Service not ready, waiting...
