Traceback (most recent call last):
  File "/workspace/manage.py", line 11, in main
    from django.core.management import execute_from_command_line
ModuleNotFoundError: No module named 'django'

The above exception was the direct cause of the following exception:

Traceback (most recent call last):
  File "/workspace/manage.py", line 22, in <module>
    main()
    ~~~~^^
  File "/workspace/manage.py", line 13, in main
    raise ImportError(
    ...<3 lines>...
    ) from exc
ImportError: Couldn't import Django. Are you sure it's installed and available on your PYTHONPATH environment variable? Did you forget to activate a virtual environment?
Watching for file changes with StatReloader
Watching for file changes with StatReloader
Watching for file changes with StatReloader
[mHTTP HEAD /login/ 200 [0.01, 127.0.0.1:44808][0m
[mHTTP GET /login/ 200 [0.01, 127.0.0.1:36596][0m
Watching for file changes with StatReloader
Watching for file changes with StatReloader
/workspace/accounts/views.py changed, reloading.
Watching for file changes with StatReloader
Watching for file changes with StatReloader
Watching for file changes with StatReloader
/workspace/accounts/views.py changed, reloading.
Watching for file changes with StatReloader
Watching for file changes with StatReloader
/workspace/accounts/views.py changed, reloading.
Watching for file changes with StatReloader
Watching for file changes with StatReloader
/workspace/accounts/views.py changed, reloading.
Watching for file changes with StatReloader
Watching for file changes with StatReloader
