[2025-08-28 20:17:48] üöÄ Starting NoctisPro Auto-Startup Service
[2025-08-28 20:17:48] ============================================
[2025-08-28 20:17:48] Static Ngrok URL: https://colt-charmed-lark.ngrok-free.app
[2025-08-28 20:17:48] Workspace: /workspace
[2025-08-28 20:17:48] Started at: Thu Aug 28 08:17:48 PM UTC 2025
[2025-08-28 20:17:48] 2025-08-28 20:17:48: üèÅ Starting main startup sequence...
[2025-08-28 20:17:48] 2025-08-28 20:17:48: üêç Starting Django server...
[2025-08-28 20:17:48] 2025-08-28 20:17:48: ‚úÖ Virtual environment activated
[2025-08-28 20:17:48] 2025-08-28 20:17:48: üîÑ Running database migrations...
[2025-08-28 20:17:49] Traceback (most recent call last):
[2025-08-28 20:17:49]   File "/workspace/venv/lib/python3.13/site-packages/django/db/backends/base/base.py", line 279, in ensure_connection
[2025-08-28 20:17:49]     self.connect()
[2025-08-28 20:17:49]     ~~~~~~~~~~~~^^
[2025-08-28 20:17:49]   File "/workspace/venv/lib/python3.13/site-packages/django/utils/asyncio.py", line 26, in inner
[2025-08-28 20:17:49]     return func(*args, **kwargs)
[2025-08-28 20:17:49]   File "/workspace/venv/lib/python3.13/site-packages/django/db/backends/base/base.py", line 256, in connect
[2025-08-28 20:17:49]     self.connection = self.get_new_connection(conn_params)
[2025-08-28 20:17:49]                       ~~~~~~~~~~~~~~~~~~~~~~~^^^^^^^^^^^^^
[2025-08-28 20:17:49]   File "/workspace/venv/lib/python3.13/site-packages/django/utils/asyncio.py", line 26, in inner
[2025-08-28 20:17:49]     return func(*args, **kwargs)
[2025-08-28 20:17:49]   File "/workspace/venv/lib/python3.13/site-packages/django/db/backends/postgresql/base.py", line 332, in get_new_connection
[2025-08-28 20:17:49]     connection = self.Database.connect(**conn_params)
[2025-08-28 20:17:49]   File "/workspace/venv/lib/python3.13/site-packages/psycopg2/__init__.py", line 122, in connect
[2025-08-28 20:17:49]     conn = _connect(dsn, connection_factory=connection_factory, **kwasync)
[2025-08-28 20:17:49] psycopg2.OperationalError: connection to server at "localhost" (::1), port 5432 failed: Connection refused
[2025-08-28 20:17:49] 	Is the server running on that host and accepting TCP/IP connections?
[2025-08-28 20:17:49] connection to server at "localhost" (127.0.0.1), port 5432 failed: Connection refused
[2025-08-28 20:17:49] 	Is the server running on that host and accepting TCP/IP connections?
[2025-08-28 20:17:49] 
[2025-08-28 20:17:49] 
[2025-08-28 20:17:49] The above exception was the direct cause of the following exception:
[2025-08-28 20:17:49] 
[2025-08-28 20:17:49] Traceback (most recent call last):
[2025-08-28 20:17:49]   File "/workspace/manage.py", line 22, in <module>
[2025-08-28 20:17:49]     main()
[2025-08-28 20:17:49]     ~~~~^^
[2025-08-28 20:17:49]   File "/workspace/manage.py", line 18, in main
[2025-08-28 20:17:49]     execute_from_command_line(sys.argv)
[2025-08-28 20:17:49]     ~~~~~~~~~~~~~~~~~~~~~~~~~^^^^^^^^^^
[2025-08-28 20:17:49]   File "/workspace/venv/lib/python3.13/site-packages/django/core/management/__init__.py", line 442, in execute_from_command_line
[2025-08-28 20:17:49]     utility.execute()
[2025-08-28 20:17:49]     ~~~~~~~~~~~~~~~^^
[2025-08-28 20:17:49]   File "/workspace/venv/lib/python3.13/site-packages/django/core/management/__init__.py", line 436, in execute
[2025-08-28 20:17:49]     self.fetch_command(subcommand).run_from_argv(self.argv)
[2025-08-28 20:17:49]     ~~~~~~~~~~~~~~~~~~~~~~~~~~~~~~~~~~~~~~~~~~~~^^^^^^^^^^^
[2025-08-28 20:17:49]   File "/workspace/venv/lib/python3.13/site-packages/django/core/management/base.py", line 416, in run_from_argv
[2025-08-28 20:17:49]     self.execute(*args, **cmd_options)
[2025-08-28 20:17:49]     ~~~~~~~~~~~~^^^^^^^^^^^^^^^^^^^^^^
[2025-08-28 20:17:49]   File "/workspace/venv/lib/python3.13/site-packages/django/core/management/base.py", line 460, in execute
[2025-08-28 20:17:49]     output = self.handle(*args, **options)
[2025-08-28 20:17:49]   File "/workspace/venv/lib/python3.13/site-packages/django/core/management/base.py", line 107, in wrapper
[2025-08-28 20:17:49]     res = handle_func(*args, **kwargs)
[2025-08-28 20:17:49]   File "/workspace/venv/lib/python3.13/site-packages/django/core/management/commands/migrate.py", line 114, in handle
[2025-08-28 20:17:49]     executor = MigrationExecutor(connection, self.migration_progress_callback)
[2025-08-28 20:17:49]   File "/workspace/venv/lib/python3.13/site-packages/django/db/migrations/executor.py", line 18, in __init__
[2025-08-28 20:17:49]     self.loader = MigrationLoader(self.connection)
[2025-08-28 20:17:49]                   ~~~~~~~~~~~~~~~^^^^^^^^^^^^^^^^^
[2025-08-28 20:17:49]   File "/workspace/venv/lib/python3.13/site-packages/django/db/migrations/loader.py", line 58, in __init__
[2025-08-28 20:17:49]     self.build_graph()
[2025-08-28 20:17:49]     ~~~~~~~~~~~~~~~~^^
[2025-08-28 20:17:49]   File "/workspace/venv/lib/python3.13/site-packages/django/db/migrations/loader.py", line 235, in build_graph
[2025-08-28 20:17:49]     self.applied_migrations = recorder.applied_migrations()
[2025-08-28 20:17:49]                               ~~~~~~~~~~~~~~~~~~~~~~~~~~~^^
[2025-08-28 20:17:49]   File "/workspace/venv/lib/python3.13/site-packages/django/db/migrations/recorder.py", line 89, in applied_migrations
[2025-08-28 20:17:49]     if self.has_table():
[2025-08-28 20:17:49]        ~~~~~~~~~~~~~~^^
[2025-08-28 20:17:49]   File "/workspace/venv/lib/python3.13/site-packages/django/db/migrations/recorder.py", line 63, in has_table
[2025-08-28 20:17:49]     with self.connection.cursor() as cursor:
[2025-08-28 20:17:49]          ~~~~~~~~~~~~~~~~~~~~~~^^
[2025-08-28 20:17:49]   File "/workspace/venv/lib/python3.13/site-packages/django/utils/asyncio.py", line 26, in inner
[2025-08-28 20:17:49]     return func(*args, **kwargs)
[2025-08-28 20:17:49]   File "/workspace/venv/lib/python3.13/site-packages/django/db/backends/base/base.py", line 320, in cursor
[2025-08-28 20:17:49]     return self._cursor()
[2025-08-28 20:17:49]            ~~~~~~~~~~~~^^
[2025-08-28 20:17:49]   File "/workspace/venv/lib/python3.13/site-packages/django/db/backends/base/base.py", line 296, in _cursor
[2025-08-28 20:17:49]     self.ensure_connection()
[2025-08-28 20:17:49]     ~~~~~~~~~~~~~~~~~~~~~~^^
[2025-08-28 20:17:49]   File "/workspace/venv/lib/python3.13/site-packages/django/utils/asyncio.py", line 26, in inner
[2025-08-28 20:17:49]     return func(*args, **kwargs)
[2025-08-28 20:17:49]   File "/workspace/venv/lib/python3.13/site-packages/django/db/backends/base/base.py", line 278, in ensure_connection
[2025-08-28 20:17:49]     with self.wrap_database_errors:
[2025-08-28 20:17:49]          ^^^^^^^^^^^^^^^^^^^^^^^^^
[2025-08-28 20:17:49]   File "/workspace/venv/lib/python3.13/site-packages/django/db/utils.py", line 91, in __exit__
[2025-08-28 20:17:49]     raise dj_exc_value.with_traceback(traceback) from exc_value
[2025-08-28 20:17:49]   File "/workspace/venv/lib/python3.13/site-packages/django/db/backends/base/base.py", line 279, in ensure_connection
[2025-08-28 20:17:49]     self.connect()
[2025-08-28 20:17:49]     ~~~~~~~~~~~~^^
[2025-08-28 20:17:49]   File "/workspace/venv/lib/python3.13/site-packages/django/utils/asyncio.py", line 26, in inner
[2025-08-28 20:17:49]     return func(*args, **kwargs)
[2025-08-28 20:17:49]   File "/workspace/venv/lib/python3.13/site-packages/django/db/backends/base/base.py", line 256, in connect
[2025-08-28 20:17:49]     self.connection = self.get_new_connection(conn_params)
[2025-08-28 20:17:49]                       ~~~~~~~~~~~~~~~~~~~~~~~^^^^^^^^^^^^^
[2025-08-28 20:17:49]   File "/workspace/venv/lib/python3.13/site-packages/django/utils/asyncio.py", line 26, in inner
[2025-08-28 20:17:49]     return func(*args, **kwargs)
[2025-08-28 20:17:49]   File "/workspace/venv/lib/python3.13/site-packages/django/db/backends/postgresql/base.py", line 332, in get_new_connection
[2025-08-28 20:17:49]     connection = self.Database.connect(**conn_params)
[2025-08-28 20:17:49]   File "/workspace/venv/lib/python3.13/site-packages/psycopg2/__init__.py", line 122, in connect
[2025-08-28 20:17:49]     conn = _connect(dsn, connection_factory=connection_factory, **kwasync)
[2025-08-28 20:17:49] django.db.utils.OperationalError: connection to server at "localhost" (::1), port 5432 failed: Connection refused
[2025-08-28 20:17:49] 	Is the server running on that host and accepting TCP/IP connections?
[2025-08-28 20:17:49] connection to server at "localhost" (127.0.0.1), port 5432 failed: Connection refused
[2025-08-28 20:17:49] 	Is the server running on that host and accepting TCP/IP connections?
[2025-08-28 20:17:49] 
[2025-08-28 20:17:49] 2025-08-28 20:17:49: üìÇ Collecting static files...
[2025-08-28 20:17:50] 
[2025-08-28 20:17:50] 163 static files copied to '/workspace/staticfiles', 2 unmodified.
[2025-08-28 20:17:50] 2025-08-28 20:17:50: üåê Starting Django/Daphne server on port 8000...
[2025-08-28 20:17:55] 2025-08-28 20:17:55: ‚úÖ Django started successfully (PID: 4122)
[2025-08-28 20:17:55] 2025-08-28 20:17:55: ‚úÖ Django startup successful
[2025-08-28 20:17:55] 2025-08-28 20:17:55: üîç Waiting for service at http://localhost:8000/health/simple/...
[2025-08-28 20:17:55] 2025-08-28 20:17:55: ‚úÖ Service is ready at http://localhost:8000/health/simple/
[2025-08-28 20:17:55] 2025-08-28 20:17:55: ‚úÖ Django is responding to health checks
[2025-08-28 20:17:55] 2025-08-28 20:17:55: üåê Attempt 1/5: Starting ngrok with static URL...
[2025-08-28 20:17:55] 2025-08-28 20:17:55: üõë Checking for existing ngrok processes...
[2025-08-28 20:17:55] 2025-08-28 20:17:55: ‚úÖ No existing ngrok processes found
[2025-08-28 20:18:05] 2025-08-28 20:18:05: ‚ùå Ngrok failed to start, checking logs...
[2025-08-28 20:18:05] 2025-08-28 20:18:05: üìÑ Ngrok log: nohup: failed to run command 'ngrok': No such file or directory
[2025-08-28 20:18:05] 2025-08-28 20:18:05: üîÑ Retrying in 15 seconds...
[2025-08-28 20:18:20] 2025-08-28 20:18:20: üåê Attempt 2/5: Starting ngrok with static URL...
[2025-08-28 20:18:20] 2025-08-28 20:18:20: üõë Checking for existing ngrok processes...
[2025-08-28 20:18:20] 2025-08-28 20:18:20: ‚úÖ No existing ngrok processes found
[2025-08-28 20:18:30] 2025-08-28 20:18:30: ‚ùå Ngrok failed to start, checking logs...
[2025-08-28 20:18:30] 2025-08-28 20:18:30: üìÑ Ngrok log: ERROR:  Install your authtoken: https://dashboard.ngrok.com/get-started/your-authtoken
[2025-08-28 20:18:30] 2025-08-28 20:18:30: üìÑ Ngrok log: ERROR:  
[2025-08-28 20:18:30] 2025-08-28 20:18:30: üìÑ Ngrok log: ERROR:  ERR_NGROK_4018
[2025-08-28 20:18:30] 2025-08-28 20:18:30: üìÑ Ngrok log: ERROR:  https://ngrok.com/docs/errors/err_ngrok_4018
[2025-08-28 20:18:30] 2025-08-28 20:18:30: üìÑ Ngrok log: ERROR:
[2025-08-28 20:18:30] 2025-08-28 20:18:30: üîÑ Retrying in 15 seconds...
[2025-08-28 20:18:45] 2025-08-28 20:18:45: üåê Attempt 3/5: Starting ngrok with static URL...
[2025-08-28 20:18:45] 2025-08-28 20:18:45: üõë Checking for existing ngrok processes...
[2025-08-28 20:18:45] 2025-08-28 20:18:45: ‚úÖ No existing ngrok processes found
[2025-08-28 20:18:55] 2025-08-28 20:18:55: ‚ùå Ngrok failed to start, checking logs...
[2025-08-28 20:18:55] 2025-08-28 20:18:55: üìÑ Ngrok log: t=2025-08-28T20:18:45+0000 lvl=info msg="no configuration paths supplied"
[2025-08-28 20:18:55] 2025-08-28 20:18:55: üìÑ Ngrok log: t=2025-08-28T20:18:45+0000 lvl=info msg="using configuration at default config path" path=/home/ubuntu/.config/ngrok/ngrok.yml
[2025-08-28 20:18:55] 2025-08-28 20:18:55: üìÑ Ngrok log: t=2025-08-28T20:18:45+0000 lvl=info msg="open config file" path=/home/ubuntu/.config/ngrok/ngrok.yml err=nil
[2025-08-28 20:18:55] 2025-08-28 20:18:55: üìÑ Ngrok log: ERROR:  You can't enable the console UI and log to stdout or stderr
[2025-08-28 20:18:55] 2025-08-28 20:18:55: üîÑ Retrying in 15 seconds...
[2025-08-28 20:19:10] 2025-08-28 20:19:10: üõë Received termination signal, cleaning up...
[2025-08-28 20:19:10] 2025-08-28 20:19:10: üõë Stopping Django...
[2025-08-28 20:19:10] 2025-08-28 20:19:10: ‚úÖ Cleanup complete
[2025-08-28 20:19:34] üöÄ Starting NoctisPro Auto-Startup Service
[2025-08-28 20:19:34] ============================================
[2025-08-28 20:19:34] Static Ngrok URL: https://colt-charmed-lark.ngrok-free.app
[2025-08-28 20:19:34] Workspace: /workspace
[2025-08-28 20:19:34] Started at: Thu Aug 28 08:19:34 PM UTC 2025
[2025-08-28 20:19:34] 2025-08-28 20:19:34: üèÅ Starting main startup sequence...
[2025-08-28 20:19:34] 2025-08-28 20:19:34: üêç Starting Django server...
[2025-08-28 20:19:34] 2025-08-28 20:19:34: ‚úÖ Virtual environment activated
[2025-08-28 20:19:34] 2025-08-28 20:19:34: üîÑ Running database migrations...
[2025-08-28 20:19:34] Traceback (most recent call last):
[2025-08-28 20:19:34]   File "/workspace/venv/lib/python3.13/site-packages/django/db/backends/base/base.py", line 279, in ensure_connection
[2025-08-28 20:19:34]     self.connect()
[2025-08-28 20:19:34]     ~~~~~~~~~~~~^^
[2025-08-28 20:19:34]   File "/workspace/venv/lib/python3.13/site-packages/django/utils/asyncio.py", line 26, in inner
[2025-08-28 20:19:34]     return func(*args, **kwargs)
[2025-08-28 20:19:34]   File "/workspace/venv/lib/python3.13/site-packages/django/db/backends/base/base.py", line 256, in connect
[2025-08-28 20:19:34]     self.connection = self.get_new_connection(conn_params)
[2025-08-28 20:19:34]                       ~~~~~~~~~~~~~~~~~~~~~~~^^^^^^^^^^^^^
[2025-08-28 20:19:34]   File "/workspace/venv/lib/python3.13/site-packages/django/utils/asyncio.py", line 26, in inner
[2025-08-28 20:19:34]     return func(*args, **kwargs)
[2025-08-28 20:19:34]   File "/workspace/venv/lib/python3.13/site-packages/django/db/backends/postgresql/base.py", line 332, in get_new_connection
[2025-08-28 20:19:34]     connection = self.Database.connect(**conn_params)
[2025-08-28 20:19:34]   File "/workspace/venv/lib/python3.13/site-packages/psycopg2/__init__.py", line 122, in connect
[2025-08-28 20:19:34]     conn = _connect(dsn, connection_factory=connection_factory, **kwasync)
[2025-08-28 20:19:34] psycopg2.OperationalError: connection to server at "localhost" (::1), port 5432 failed: Connection refused
[2025-08-28 20:19:34] 	Is the server running on that host and accepting TCP/IP connections?
[2025-08-28 20:19:34] connection to server at "localhost" (127.0.0.1), port 5432 failed: Connection refused
[2025-08-28 20:19:34] 	Is the server running on that host and accepting TCP/IP connections?
[2025-08-28 20:19:34] 
[2025-08-28 20:19:34] 
[2025-08-28 20:19:34] The above exception was the direct cause of the following exception:
[2025-08-28 20:19:34] 
[2025-08-28 20:19:34] Traceback (most recent call last):
[2025-08-28 20:19:34]   File "/workspace/manage.py", line 22, in <module>
[2025-08-28 20:19:34]     main()
[2025-08-28 20:19:34]     ~~~~^^
[2025-08-28 20:19:34]   File "/workspace/manage.py", line 18, in main
[2025-08-28 20:19:34]     execute_from_command_line(sys.argv)
[2025-08-28 20:19:34]     ~~~~~~~~~~~~~~~~~~~~~~~~~^^^^^^^^^^
[2025-08-28 20:19:34]   File "/workspace/venv/lib/python3.13/site-packages/django/core/management/__init__.py", line 442, in execute_from_command_line
[2025-08-28 20:19:34]     utility.execute()
[2025-08-28 20:19:34]     ~~~~~~~~~~~~~~~^^
[2025-08-28 20:19:34]   File "/workspace/venv/lib/python3.13/site-packages/django/core/management/__init__.py", line 436, in execute
[2025-08-28 20:19:34]     self.fetch_command(subcommand).run_from_argv(self.argv)
[2025-08-28 20:19:34]     ~~~~~~~~~~~~~~~~~~~~~~~~~~~~~~~~~~~~~~~~~~~~^^^^^^^^^^^
[2025-08-28 20:19:34]   File "/workspace/venv/lib/python3.13/site-packages/django/core/management/base.py", line 416, in run_from_argv
[2025-08-28 20:19:34]     self.execute(*args, **cmd_options)
[2025-08-28 20:19:34]     ~~~~~~~~~~~~^^^^^^^^^^^^^^^^^^^^^^
[2025-08-28 20:19:34]   File "/workspace/venv/lib/python3.13/site-packages/django/core/management/base.py", line 460, in execute
[2025-08-28 20:19:34]     output = self.handle(*args, **options)
[2025-08-28 20:19:34]   File "/workspace/venv/lib/python3.13/site-packages/django/core/management/base.py", line 107, in wrapper
[2025-08-28 20:19:34]     res = handle_func(*args, **kwargs)
[2025-08-28 20:19:34]   File "/workspace/venv/lib/python3.13/site-packages/django/core/management/commands/migrate.py", line 114, in handle
[2025-08-28 20:19:34]     executor = MigrationExecutor(connection, self.migration_progress_callback)
[2025-08-28 20:19:34]   File "/workspace/venv/lib/python3.13/site-packages/django/db/migrations/executor.py", line 18, in __init__
[2025-08-28 20:19:34]     self.loader = MigrationLoader(self.connection)
[2025-08-28 20:19:34]                   ~~~~~~~~~~~~~~~^^^^^^^^^^^^^^^^^
[2025-08-28 20:19:34]   File "/workspace/venv/lib/python3.13/site-packages/django/db/migrations/loader.py", line 58, in __init__
[2025-08-28 20:19:34]     self.build_graph()
[2025-08-28 20:19:34]     ~~~~~~~~~~~~~~~~^^
[2025-08-28 20:19:34]   File "/workspace/venv/lib/python3.13/site-packages/django/db/migrations/loader.py", line 235, in build_graph
[2025-08-28 20:19:34]     self.applied_migrations = recorder.applied_migrations()
[2025-08-28 20:19:34]                               ~~~~~~~~~~~~~~~~~~~~~~~~~~~^^
[2025-08-28 20:19:34]   File "/workspace/venv/lib/python3.13/site-packages/django/db/migrations/recorder.py", line 89, in applied_migrations
[2025-08-28 20:19:34]     if self.has_table():
[2025-08-28 20:19:34]        ~~~~~~~~~~~~~~^^
[2025-08-28 20:19:34]   File "/workspace/venv/lib/python3.13/site-packages/django/db/migrations/recorder.py", line 63, in has_table
[2025-08-28 20:19:34]     with self.connection.cursor() as cursor:
[2025-08-28 20:19:34]          ~~~~~~~~~~~~~~~~~~~~~~^^
[2025-08-28 20:19:34]   File "/workspace/venv/lib/python3.13/site-packages/django/utils/asyncio.py", line 26, in inner
[2025-08-28 20:19:34]     return func(*args, **kwargs)
[2025-08-28 20:19:34]   File "/workspace/venv/lib/python3.13/site-packages/django/db/backends/base/base.py", line 320, in cursor
[2025-08-28 20:19:34]     return self._cursor()
[2025-08-28 20:19:34]            ~~~~~~~~~~~~^^
[2025-08-28 20:19:34]   File "/workspace/venv/lib/python3.13/site-packages/django/db/backends/base/base.py", line 296, in _cursor
[2025-08-28 20:19:34]     self.ensure_connection()
[2025-08-28 20:19:34]     ~~~~~~~~~~~~~~~~~~~~~~^^
[2025-08-28 20:19:34]   File "/workspace/venv/lib/python3.13/site-packages/django/utils/asyncio.py", line 26, in inner
[2025-08-28 20:19:34]     return func(*args, **kwargs)
[2025-08-28 20:19:34]   File "/workspace/venv/lib/python3.13/site-packages/django/db/backends/base/base.py", line 278, in ensure_connection
[2025-08-28 20:19:34]     with self.wrap_database_errors:
[2025-08-28 20:19:34]          ^^^^^^^^^^^^^^^^^^^^^^^^^
[2025-08-28 20:19:34]   File "/workspace/venv/lib/python3.13/site-packages/django/db/utils.py", line 91, in __exit__
[2025-08-28 20:19:34]     raise dj_exc_value.with_traceback(traceback) from exc_value
[2025-08-28 20:19:34]   File "/workspace/venv/lib/python3.13/site-packages/django/db/backends/base/base.py", line 279, in ensure_connection
[2025-08-28 20:19:35]     self.connect()
[2025-08-28 20:19:35]     ~~~~~~~~~~~~^^
[2025-08-28 20:19:35]   File "/workspace/venv/lib/python3.13/site-packages/django/utils/asyncio.py", line 26, in inner
[2025-08-28 20:19:35]     return func(*args, **kwargs)
[2025-08-28 20:19:35]   File "/workspace/venv/lib/python3.13/site-packages/django/db/backends/base/base.py", line 256, in connect
[2025-08-28 20:19:35]     self.connection = self.get_new_connection(conn_params)
[2025-08-28 20:19:35]                       ~~~~~~~~~~~~~~~~~~~~~~~^^^^^^^^^^^^^
[2025-08-28 20:19:35]   File "/workspace/venv/lib/python3.13/site-packages/django/utils/asyncio.py", line 26, in inner
[2025-08-28 20:19:35]     return func(*args, **kwargs)
[2025-08-28 20:19:35]   File "/workspace/venv/lib/python3.13/site-packages/django/db/backends/postgresql/base.py", line 332, in get_new_connection
[2025-08-28 20:19:35]     connection = self.Database.connect(**conn_params)
[2025-08-28 20:19:35]   File "/workspace/venv/lib/python3.13/site-packages/psycopg2/__init__.py", line 122, in connect
[2025-08-28 20:19:35]     conn = _connect(dsn, connection_factory=connection_factory, **kwasync)
[2025-08-28 20:19:35] django.db.utils.OperationalError: connection to server at "localhost" (::1), port 5432 failed: Connection refused
[2025-08-28 20:19:35] 	Is the server running on that host and accepting TCP/IP connections?
[2025-08-28 20:19:35] connection to server at "localhost" (127.0.0.1), port 5432 failed: Connection refused
[2025-08-28 20:19:35] 	Is the server running on that host and accepting TCP/IP connections?
[2025-08-28 20:19:35] 
[2025-08-28 20:19:35] 2025-08-28 20:19:35: üìÇ Collecting static files...
[2025-08-28 20:19:35] 
[2025-08-28 20:19:35] 0 static files copied to '/workspace/staticfiles', 165 unmodified.
[2025-08-28 20:19:35] 2025-08-28 20:19:35: üåê Starting Django/Daphne server on port 8000...
[2025-08-28 20:19:40] 2025-08-28 20:19:40: ‚úÖ Django started successfully (PID: 5104)
[2025-08-28 20:19:40] 2025-08-28 20:19:40: ‚úÖ Django startup successful
[2025-08-28 20:19:40] 2025-08-28 20:19:40: üîç Waiting for service at http://localhost:8000/health/simple/...
[2025-08-28 20:19:40] 2025-08-28 20:19:40: ‚úÖ Service is ready at http://localhost:8000/health/simple/
[2025-08-28 20:19:40] 2025-08-28 20:19:40: ‚úÖ Django is responding to health checks
[2025-08-28 20:19:40] 2025-08-28 20:19:40: üåê Attempt 1/5: Starting ngrok with static URL...
[2025-08-28 20:19:40] 2025-08-28 20:19:40: üõë Checking for existing ngrok processes...
[2025-08-28 20:19:40] 2025-08-28 20:19:40: ‚úÖ No existing ngrok processes found
[2025-08-28 20:19:50] 2025-08-28 20:19:50: ‚ùå Ngrok failed to start, checking logs...
[2025-08-28 20:19:50] 2025-08-28 20:19:50: üìÑ Ngrok log: t=2025-08-28T20:19:40+0000 lvl=info msg="no configuration paths supplied"
[2025-08-28 20:19:50] 2025-08-28 20:19:50: üìÑ Ngrok log: t=2025-08-28T20:19:40+0000 lvl=info msg="using configuration at default config path" path=/home/ubuntu/.config/ngrok/ngrok.yml
[2025-08-28 20:19:50] 2025-08-28 20:19:50: üìÑ Ngrok log: t=2025-08-28T20:19:40+0000 lvl=info msg="open config file" path=/home/ubuntu/.config/ngrok/ngrok.yml err=nil
[2025-08-28 20:19:50] 2025-08-28 20:19:50: üìÑ Ngrok log: ERROR:  You can't enable the console UI and log to stdout or stderr
[2025-08-28 20:19:50] 2025-08-28 20:19:50: üîÑ Retrying in 15 seconds...
[2025-08-28 20:20:05] 2025-08-28 20:20:05: üåê Attempt 2/5: Starting ngrok with static URL...
[2025-08-28 20:20:05] 2025-08-28 20:20:05: üõë Checking for existing ngrok processes...
[2025-08-28 20:20:05] 2025-08-28 20:20:05: ‚úÖ No existing ngrok processes found
[2025-08-28 20:20:15] 2025-08-28 20:20:15: üõë Received termination signal, cleaning up...
[2025-08-28 20:20:15] 2025-08-28 20:20:15: üõë Stopping Django...
[2025-08-28 20:20:15] 2025-08-28 20:20:15: ‚úÖ Cleanup complete
[2025-08-28 20:20:42] üöÄ Starting NoctisPro Auto-Startup Service
[2025-08-28 20:20:42] ============================================
[2025-08-28 20:20:42] Static Ngrok URL: https://colt-charmed-lark.ngrok-free.app
[2025-08-28 20:20:42] Workspace: /workspace
[2025-08-28 20:20:42] Started at: Thu Aug 28 08:20:42 PM UTC 2025
[2025-08-28 20:20:42] 2025-08-28 20:20:42: üèÅ Starting main startup sequence...
[2025-08-28 20:20:42] 2025-08-28 20:20:42: üêç Starting Django server...
[2025-08-28 20:20:42] 2025-08-28 20:20:42: ‚úÖ Virtual environment activated
[2025-08-28 20:20:42] 2025-08-28 20:20:42: üîÑ Running database migrations...
[2025-08-28 20:20:43] Traceback (most recent call last):
[2025-08-28 20:20:43]   File "/workspace/venv/lib/python3.13/site-packages/django/db/backends/base/base.py", line 279, in ensure_connection
[2025-08-28 20:20:43]     self.connect()
[2025-08-28 20:20:43]     ~~~~~~~~~~~~^^
[2025-08-28 20:20:43]   File "/workspace/venv/lib/python3.13/site-packages/django/utils/asyncio.py", line 26, in inner
[2025-08-28 20:20:43]     return func(*args, **kwargs)
[2025-08-28 20:20:43]   File "/workspace/venv/lib/python3.13/site-packages/django/db/backends/base/base.py", line 256, in connect
[2025-08-28 20:20:43]     self.connection = self.get_new_connection(conn_params)
[2025-08-28 20:20:43]                       ~~~~~~~~~~~~~~~~~~~~~~~^^^^^^^^^^^^^
[2025-08-28 20:20:43]   File "/workspace/venv/lib/python3.13/site-packages/django/utils/asyncio.py", line 26, in inner
[2025-08-28 20:20:43]     return func(*args, **kwargs)
[2025-08-28 20:20:43]   File "/workspace/venv/lib/python3.13/site-packages/django/db/backends/postgresql/base.py", line 332, in get_new_connection
[2025-08-28 20:20:43]     connection = self.Database.connect(**conn_params)
[2025-08-28 20:20:43]   File "/workspace/venv/lib/python3.13/site-packages/psycopg2/__init__.py", line 122, in connect
[2025-08-28 20:20:43]     conn = _connect(dsn, connection_factory=connection_factory, **kwasync)
[2025-08-28 20:20:43] psycopg2.OperationalError: connection to server at "localhost" (::1), port 5432 failed: Connection refused
[2025-08-28 20:20:43] 	Is the server running on that host and accepting TCP/IP connections?
[2025-08-28 20:20:43] connection to server at "localhost" (127.0.0.1), port 5432 failed: Connection refused
[2025-08-28 20:20:43] 	Is the server running on that host and accepting TCP/IP connections?
[2025-08-28 20:20:43] 
[2025-08-28 20:20:43] 
[2025-08-28 20:20:43] The above exception was the direct cause of the following exception:
[2025-08-28 20:20:43] 
[2025-08-28 20:20:43] Traceback (most recent call last):
[2025-08-28 20:20:43]   File "/workspace/manage.py", line 22, in <module>
[2025-08-28 20:20:43]     main()
[2025-08-28 20:20:43]     ~~~~^^
[2025-08-28 20:20:43]   File "/workspace/manage.py", line 18, in main
[2025-08-28 20:20:43]     execute_from_command_line(sys.argv)
[2025-08-28 20:20:43]     ~~~~~~~~~~~~~~~~~~~~~~~~~^^^^^^^^^^
[2025-08-28 20:20:43]   File "/workspace/venv/lib/python3.13/site-packages/django/core/management/__init__.py", line 442, in execute_from_command_line
[2025-08-28 20:20:43]     utility.execute()
[2025-08-28 20:20:43]     ~~~~~~~~~~~~~~~^^
[2025-08-28 20:20:43]   File "/workspace/venv/lib/python3.13/site-packages/django/core/management/__init__.py", line 436, in execute
[2025-08-28 20:20:43]     self.fetch_command(subcommand).run_from_argv(self.argv)
[2025-08-28 20:20:43]     ~~~~~~~~~~~~~~~~~~~~~~~~~~~~~~~~~~~~~~~~~~~~^^^^^^^^^^^
[2025-08-28 20:20:43]   File "/workspace/venv/lib/python3.13/site-packages/django/core/management/base.py", line 416, in run_from_argv
[2025-08-28 20:20:43]     self.execute(*args, **cmd_options)
[2025-08-28 20:20:43]     ~~~~~~~~~~~~^^^^^^^^^^^^^^^^^^^^^^
[2025-08-28 20:20:43]   File "/workspace/venv/lib/python3.13/site-packages/django/core/management/base.py", line 460, in execute
[2025-08-28 20:20:43]     output = self.handle(*args, **options)
[2025-08-28 20:20:43]   File "/workspace/venv/lib/python3.13/site-packages/django/core/management/base.py", line 107, in wrapper
[2025-08-28 20:20:43]     res = handle_func(*args, **kwargs)
[2025-08-28 20:20:43]   File "/workspace/venv/lib/python3.13/site-packages/django/core/management/commands/migrate.py", line 114, in handle
[2025-08-28 20:20:43]     executor = MigrationExecutor(connection, self.migration_progress_callback)
[2025-08-28 20:20:43]   File "/workspace/venv/lib/python3.13/site-packages/django/db/migrations/executor.py", line 18, in __init__
[2025-08-28 20:20:43]     self.loader = MigrationLoader(self.connection)
[2025-08-28 20:20:43]                   ~~~~~~~~~~~~~~~^^^^^^^^^^^^^^^^^
[2025-08-28 20:20:43]   File "/workspace/venv/lib/python3.13/site-packages/django/db/migrations/loader.py", line 58, in __init__
[2025-08-28 20:20:43]     self.build_graph()
[2025-08-28 20:20:43]     ~~~~~~~~~~~~~~~~^^
[2025-08-28 20:20:43]   File "/workspace/venv/lib/python3.13/site-packages/django/db/migrations/loader.py", line 235, in build_graph
[2025-08-28 20:20:43]     self.applied_migrations = recorder.applied_migrations()
[2025-08-28 20:20:43]                               ~~~~~~~~~~~~~~~~~~~~~~~~~~~^^
[2025-08-28 20:20:43]   File "/workspace/venv/lib/python3.13/site-packages/django/db/migrations/recorder.py", line 89, in applied_migrations
[2025-08-28 20:20:43]     if self.has_table():
[2025-08-28 20:20:43]        ~~~~~~~~~~~~~~^^
[2025-08-28 20:20:43]   File "/workspace/venv/lib/python3.13/site-packages/django/db/migrations/recorder.py", line 63, in has_table
[2025-08-28 20:20:43]     with self.connection.cursor() as cursor:
[2025-08-28 20:20:43]          ~~~~~~~~~~~~~~~~~~~~~~^^
[2025-08-28 20:20:43]   File "/workspace/venv/lib/python3.13/site-packages/django/utils/asyncio.py", line 26, in inner
[2025-08-28 20:20:43]     return func(*args, **kwargs)
[2025-08-28 20:20:43]   File "/workspace/venv/lib/python3.13/site-packages/django/db/backends/base/base.py", line 320, in cursor
[2025-08-28 20:20:43]     return self._cursor()
[2025-08-28 20:20:43]            ~~~~~~~~~~~~^^
[2025-08-28 20:20:43]   File "/workspace/venv/lib/python3.13/site-packages/django/db/backends/base/base.py", line 296, in _cursor
[2025-08-28 20:20:43]     self.ensure_connection()
[2025-08-28 20:20:43]     ~~~~~~~~~~~~~~~~~~~~~~^^
[2025-08-28 20:20:43]   File "/workspace/venv/lib/python3.13/site-packages/django/utils/asyncio.py", line 26, in inner
[2025-08-28 20:20:43]     return func(*args, **kwargs)
[2025-08-28 20:20:43]   File "/workspace/venv/lib/python3.13/site-packages/django/db/backends/base/base.py", line 278, in ensure_connection
[2025-08-28 20:20:43]     with self.wrap_database_errors:
[2025-08-28 20:20:43]          ^^^^^^^^^^^^^^^^^^^^^^^^^
[2025-08-28 20:20:43]   File "/workspace/venv/lib/python3.13/site-packages/django/db/utils.py", line 91, in __exit__
[2025-08-28 20:20:43]     raise dj_exc_value.with_traceback(traceback) from exc_value
[2025-08-28 20:20:43]   File "/workspace/venv/lib/python3.13/site-packages/django/db/backends/base/base.py", line 279, in ensure_connection
[2025-08-28 20:20:43]     self.connect()
[2025-08-28 20:20:43]     ~~~~~~~~~~~~^^
[2025-08-28 20:20:43]   File "/workspace/venv/lib/python3.13/site-packages/django/utils/asyncio.py", line 26, in inner
[2025-08-28 20:20:43]     return func(*args, **kwargs)
[2025-08-28 20:20:43]   File "/workspace/venv/lib/python3.13/site-packages/django/db/backends/base/base.py", line 256, in connect
[2025-08-28 20:20:43]     self.connection = self.get_new_connection(conn_params)
[2025-08-28 20:20:43]                       ~~~~~~~~~~~~~~~~~~~~~~~^^^^^^^^^^^^^
[2025-08-28 20:20:43]   File "/workspace/venv/lib/python3.13/site-packages/django/utils/asyncio.py", line 26, in inner
[2025-08-28 20:20:43]     return func(*args, **kwargs)
[2025-08-28 20:20:43]   File "/workspace/venv/lib/python3.13/site-packages/django/db/backends/postgresql/base.py", line 332, in get_new_connection
[2025-08-28 20:20:43]     connection = self.Database.connect(**conn_params)
[2025-08-28 20:20:43]   File "/workspace/venv/lib/python3.13/site-packages/psycopg2/__init__.py", line 122, in connect
[2025-08-28 20:20:43]     conn = _connect(dsn, connection_factory=connection_factory, **kwasync)
[2025-08-28 20:20:43] django.db.utils.OperationalError: connection to server at "localhost" (::1), port 5432 failed: Connection refused
[2025-08-28 20:20:43] 	Is the server running on that host and accepting TCP/IP connections?
[2025-08-28 20:20:43] connection to server at "localhost" (127.0.0.1), port 5432 failed: Connection refused
[2025-08-28 20:20:43] 	Is the server running on that host and accepting TCP/IP connections?
[2025-08-28 20:20:43] 
[2025-08-28 20:20:43] 2025-08-28 20:20:43: üìÇ Collecting static files...
[2025-08-28 20:20:43] 
[2025-08-28 20:20:43] 0 static files copied to '/workspace/staticfiles', 165 unmodified.
[2025-08-28 20:20:43] 2025-08-28 20:20:43: üåê Starting Django/Daphne server on port 8000...
[2025-08-28 20:20:48] 2025-08-28 20:20:48: ‚úÖ Django started successfully (PID: 5841)
[2025-08-28 20:20:48] 2025-08-28 20:20:48: ‚úÖ Django startup successful
[2025-08-28 20:20:48] 2025-08-28 20:20:48: üîç Waiting for service at http://localhost:8000/health/simple/...
[2025-08-28 20:20:48] 2025-08-28 20:20:48: ‚úÖ Service is ready at http://localhost:8000/health/simple/
[2025-08-28 20:20:48] 2025-08-28 20:20:48: ‚úÖ Django is responding to health checks
[2025-08-28 20:20:48] 2025-08-28 20:20:48: üåê Attempt 1/5: Starting ngrok with static URL...
[2025-08-28 20:20:48] 2025-08-28 20:20:48: üõë Checking for existing ngrok processes...
[2025-08-28 20:20:48] 2025-08-28 20:20:48: ‚úÖ No existing ngrok processes found
[2025-08-28 20:20:58] 2025-08-28 20:20:58: ‚ùå Ngrok failed to start, checking logs...
[2025-08-28 20:20:58] 2025-08-28 20:20:58: üìÑ Ngrok log: ERROR:  unknown flag: --console-ui
[2025-08-28 20:20:58] 2025-08-28 20:20:58: üîÑ Retrying in 15 seconds...
[2025-08-28 20:21:13] 2025-08-28 20:21:13: üåê Attempt 2/5: Starting ngrok with static URL...
[2025-08-28 20:21:13] 2025-08-28 20:21:13: üõë Checking for existing ngrok processes...
[2025-08-28 20:21:13] 2025-08-28 20:21:13: ‚úÖ No existing ngrok processes found
[2025-08-28 20:21:23] 2025-08-28 20:21:23: ‚ùå Ngrok failed to start, checking logs...
[2025-08-28 20:21:23] 2025-08-28 20:21:23: üìÑ Ngrok log: ERROR:  unknown flag: --console-ui
[2025-08-28 20:21:23] 2025-08-28 20:21:23: üîÑ Retrying in 15 seconds...
[2025-08-28 20:21:38] 2025-08-28 20:21:38: üõë Received termination signal, cleaning up...
[2025-08-28 20:21:38] 2025-08-28 20:21:38: üõë Stopping Django...
[2025-08-28 20:21:38] 2025-08-28 20:21:38: ‚úÖ Cleanup complete
[2025-08-28 20:22:04] üöÄ Starting NoctisPro Auto-Startup Service
[2025-08-28 20:22:04] ============================================
[2025-08-28 20:22:04] Static Ngrok URL: https://colt-charmed-lark.ngrok-free.app
[2025-08-28 20:22:04] Workspace: /workspace
[2025-08-28 20:22:04] Started at: Thu Aug 28 08:22:04 PM UTC 2025
[2025-08-28 20:22:04] 2025-08-28 20:22:04: üèÅ Starting main startup sequence...
[2025-08-28 20:22:04] 2025-08-28 20:22:04: üêç Starting Django server...
[2025-08-28 20:22:04] 2025-08-28 20:22:04: ‚úÖ Virtual environment activated
[2025-08-28 20:22:04] 2025-08-28 20:22:04: üîÑ Running database migrations...
[2025-08-28 20:22:05] Traceback (most recent call last):
[2025-08-28 20:22:05]   File "/workspace/venv/lib/python3.13/site-packages/django/db/backends/base/base.py", line 279, in ensure_connection
[2025-08-28 20:22:05]     self.connect()
[2025-08-28 20:22:05]     ~~~~~~~~~~~~^^
[2025-08-28 20:22:05]   File "/workspace/venv/lib/python3.13/site-packages/django/utils/asyncio.py", line 26, in inner
[2025-08-28 20:22:05]     return func(*args, **kwargs)
[2025-08-28 20:22:05]   File "/workspace/venv/lib/python3.13/site-packages/django/db/backends/base/base.py", line 256, in connect
[2025-08-28 20:22:05]     self.connection = self.get_new_connection(conn_params)
[2025-08-28 20:22:05]                       ~~~~~~~~~~~~~~~~~~~~~~~^^^^^^^^^^^^^
[2025-08-28 20:22:05]   File "/workspace/venv/lib/python3.13/site-packages/django/utils/asyncio.py", line 26, in inner
[2025-08-28 20:22:05]     return func(*args, **kwargs)
[2025-08-28 20:22:05]   File "/workspace/venv/lib/python3.13/site-packages/django/db/backends/postgresql/base.py", line 332, in get_new_connection
[2025-08-28 20:22:05]     connection = self.Database.connect(**conn_params)
[2025-08-28 20:22:05]   File "/workspace/venv/lib/python3.13/site-packages/psycopg2/__init__.py", line 122, in connect
[2025-08-28 20:22:05]     conn = _connect(dsn, connection_factory=connection_factory, **kwasync)
[2025-08-28 20:22:05] psycopg2.OperationalError: connection to server at "localhost" (::1), port 5432 failed: Connection refused
[2025-08-28 20:22:05] 	Is the server running on that host and accepting TCP/IP connections?
[2025-08-28 20:22:05] connection to server at "localhost" (127.0.0.1), port 5432 failed: Connection refused
[2025-08-28 20:22:05] 	Is the server running on that host and accepting TCP/IP connections?
[2025-08-28 20:22:05] 
[2025-08-28 20:22:05] 
[2025-08-28 20:22:05] The above exception was the direct cause of the following exception:
[2025-08-28 20:22:05] 
[2025-08-28 20:22:05] Traceback (most recent call last):
[2025-08-28 20:22:05]   File "/workspace/manage.py", line 22, in <module>
[2025-08-28 20:22:05]     main()
[2025-08-28 20:22:05]     ~~~~^^
[2025-08-28 20:22:05]   File "/workspace/manage.py", line 18, in main
[2025-08-28 20:22:05]     execute_from_command_line(sys.argv)
[2025-08-28 20:22:05]     ~~~~~~~~~~~~~~~~~~~~~~~~~^^^^^^^^^^
[2025-08-28 20:22:05]   File "/workspace/venv/lib/python3.13/site-packages/django/core/management/__init__.py", line 442, in execute_from_command_line
[2025-08-28 20:22:05]     utility.execute()
[2025-08-28 20:22:05]     ~~~~~~~~~~~~~~~^^
[2025-08-28 20:22:05]   File "/workspace/venv/lib/python3.13/site-packages/django/core/management/__init__.py", line 436, in execute
[2025-08-28 20:22:05]     self.fetch_command(subcommand).run_from_argv(self.argv)
[2025-08-28 20:22:05]     ~~~~~~~~~~~~~~~~~~~~~~~~~~~~~~~~~~~~~~~~~~~~^^^^^^^^^^^
[2025-08-28 20:22:05]   File "/workspace/venv/lib/python3.13/site-packages/django/core/management/base.py", line 416, in run_from_argv
[2025-08-28 20:22:05]     self.execute(*args, **cmd_options)
[2025-08-28 20:22:05]     ~~~~~~~~~~~~^^^^^^^^^^^^^^^^^^^^^^
[2025-08-28 20:22:05]   File "/workspace/venv/lib/python3.13/site-packages/django/core/management/base.py", line 460, in execute
[2025-08-28 20:22:05]     output = self.handle(*args, **options)
[2025-08-28 20:22:05]   File "/workspace/venv/lib/python3.13/site-packages/django/core/management/base.py", line 107, in wrapper
[2025-08-28 20:22:05]     res = handle_func(*args, **kwargs)
[2025-08-28 20:22:05]   File "/workspace/venv/lib/python3.13/site-packages/django/core/management/commands/migrate.py", line 114, in handle
[2025-08-28 20:22:05]     executor = MigrationExecutor(connection, self.migration_progress_callback)
[2025-08-28 20:22:05]   File "/workspace/venv/lib/python3.13/site-packages/django/db/migrations/executor.py", line 18, in __init__
[2025-08-28 20:22:05]     self.loader = MigrationLoader(self.connection)
[2025-08-28 20:22:05]                   ~~~~~~~~~~~~~~~^^^^^^^^^^^^^^^^^
[2025-08-28 20:22:05]   File "/workspace/venv/lib/python3.13/site-packages/django/db/migrations/loader.py", line 58, in __init__
[2025-08-28 20:22:05]     self.build_graph()
[2025-08-28 20:22:05]     ~~~~~~~~~~~~~~~~^^
[2025-08-28 20:22:05]   File "/workspace/venv/lib/python3.13/site-packages/django/db/migrations/loader.py", line 235, in build_graph
[2025-08-28 20:22:05]     self.applied_migrations = recorder.applied_migrations()
[2025-08-28 20:22:05]                               ~~~~~~~~~~~~~~~~~~~~~~~~~~~^^
[2025-08-28 20:22:05]   File "/workspace/venv/lib/python3.13/site-packages/django/db/migrations/recorder.py", line 89, in applied_migrations
[2025-08-28 20:22:05]     if self.has_table():
[2025-08-28 20:22:05]        ~~~~~~~~~~~~~~^^
[2025-08-28 20:22:05]   File "/workspace/venv/lib/python3.13/site-packages/django/db/migrations/recorder.py", line 63, in has_table
[2025-08-28 20:22:05]     with self.connection.cursor() as cursor:
[2025-08-28 20:22:05]          ~~~~~~~~~~~~~~~~~~~~~~^^
[2025-08-28 20:22:05]   File "/workspace/venv/lib/python3.13/site-packages/django/utils/asyncio.py", line 26, in inner
[2025-08-28 20:22:05]     return func(*args, **kwargs)
[2025-08-28 20:22:05]   File "/workspace/venv/lib/python3.13/site-packages/django/db/backends/base/base.py", line 320, in cursor
[2025-08-28 20:22:05]     return self._cursor()
[2025-08-28 20:22:05]            ~~~~~~~~~~~~^^
[2025-08-28 20:22:05]   File "/workspace/venv/lib/python3.13/site-packages/django/db/backends/base/base.py", line 296, in _cursor
[2025-08-28 20:22:05]     self.ensure_connection()
[2025-08-28 20:22:05]     ~~~~~~~~~~~~~~~~~~~~~~^^
[2025-08-28 20:22:05]   File "/workspace/venv/lib/python3.13/site-packages/django/utils/asyncio.py", line 26, in inner
[2025-08-28 20:22:05]     return func(*args, **kwargs)
[2025-08-28 20:22:05]   File "/workspace/venv/lib/python3.13/site-packages/django/db/backends/base/base.py", line 278, in ensure_connection
[2025-08-28 20:22:05]     with self.wrap_database_errors:
[2025-08-28 20:22:05]          ^^^^^^^^^^^^^^^^^^^^^^^^^
[2025-08-28 20:22:05]   File "/workspace/venv/lib/python3.13/site-packages/django/db/utils.py", line 91, in __exit__
[2025-08-28 20:22:05]     raise dj_exc_value.with_traceback(traceback) from exc_value
[2025-08-28 20:22:05]   File "/workspace/venv/lib/python3.13/site-packages/django/db/backends/base/base.py", line 279, in ensure_connection
[2025-08-28 20:22:05]     self.connect()
[2025-08-28 20:22:05]     ~~~~~~~~~~~~^^
[2025-08-28 20:22:05]   File "/workspace/venv/lib/python3.13/site-packages/django/utils/asyncio.py", line 26, in inner
[2025-08-28 20:22:05]     return func(*args, **kwargs)
[2025-08-28 20:22:05]   File "/workspace/venv/lib/python3.13/site-packages/django/db/backends/base/base.py", line 256, in connect
[2025-08-28 20:22:05]     self.connection = self.get_new_connection(conn_params)
[2025-08-28 20:22:05]                       ~~~~~~~~~~~~~~~~~~~~~~~^^^^^^^^^^^^^
[2025-08-28 20:22:05]   File "/workspace/venv/lib/python3.13/site-packages/django/utils/asyncio.py", line 26, in inner
[2025-08-28 20:22:05]     return func(*args, **kwargs)
[2025-08-28 20:22:05]   File "/workspace/venv/lib/python3.13/site-packages/django/db/backends/postgresql/base.py", line 332, in get_new_connection
[2025-08-28 20:22:05]     connection = self.Database.connect(**conn_params)
[2025-08-28 20:22:05]   File "/workspace/venv/lib/python3.13/site-packages/psycopg2/__init__.py", line 122, in connect
[2025-08-28 20:22:05]     conn = _connect(dsn, connection_factory=connection_factory, **kwasync)
[2025-08-28 20:22:05] django.db.utils.OperationalError: connection to server at "localhost" (::1), port 5432 failed: Connection refused
[2025-08-28 20:22:05] 	Is the server running on that host and accepting TCP/IP connections?
[2025-08-28 20:22:05] connection to server at "localhost" (127.0.0.1), port 5432 failed: Connection refused
[2025-08-28 20:22:05] 	Is the server running on that host and accepting TCP/IP connections?
[2025-08-28 20:22:05] 
[2025-08-28 20:22:05] 2025-08-28 20:22:05: üìÇ Collecting static files...
[2025-08-28 20:22:05] 
[2025-08-28 20:22:05] 0 static files copied to '/workspace/staticfiles', 165 unmodified.
[2025-08-28 20:22:05] 2025-08-28 20:22:05: üåê Starting Django/Daphne server on port 8000...
[2025-08-28 20:22:10] 2025-08-28 20:22:10: ‚úÖ Django started successfully (PID: 6818)
[2025-08-28 20:22:10] 2025-08-28 20:22:10: ‚úÖ Django startup successful
[2025-08-28 20:22:10] 2025-08-28 20:22:10: üîç Waiting for service at http://localhost:8000/health/simple/...
[2025-08-28 20:22:11] 2025-08-28 20:22:11: ‚úÖ Service is ready at http://localhost:8000/health/simple/
[2025-08-28 20:22:11] 2025-08-28 20:22:11: ‚úÖ Django is responding to health checks
[2025-08-28 20:22:11] 2025-08-28 20:22:11: üåê Attempt 1/5: Starting ngrok with static URL...
[2025-08-28 20:22:11] 2025-08-28 20:22:11: üõë Checking for existing ngrok processes...
[2025-08-28 20:22:11] 2025-08-28 20:22:11: ‚úÖ No existing ngrok processes found
[2025-08-28 20:22:21] 2025-08-28 20:22:21: ‚ùå Ngrok failed to start, checking logs...
[2025-08-28 20:22:21] 2025-08-28 20:22:21: üìÑ Ngrok log: t=2025-08-28T20:22:11+0000 lvl=info msg="no configuration paths supplied"
[2025-08-28 20:22:21] 2025-08-28 20:22:21: üìÑ Ngrok log: t=2025-08-28T20:22:11+0000 lvl=info msg="using configuration at default config path" path=/home/ubuntu/.config/ngrok/ngrok.yml
[2025-08-28 20:22:21] 2025-08-28 20:22:21: üìÑ Ngrok log: t=2025-08-28T20:22:11+0000 lvl=info msg="open config file" path=/home/ubuntu/.config/ngrok/ngrok.yml err=nil
[2025-08-28 20:22:21] 2025-08-28 20:22:21: üìÑ Ngrok log: ERROR:  You can't enable the console UI and log to stdout or stderr
[2025-08-28 20:22:21] 2025-08-28 20:22:21: üîÑ Retrying in 15 seconds...
[2025-08-28 20:22:36] 2025-08-28 20:22:36: üåê Attempt 2/5: Starting ngrok with static URL...
[2025-08-28 20:22:36] 2025-08-28 20:22:36: üõë Checking for existing ngrok processes...
[2025-08-28 20:22:36] 2025-08-28 20:22:36: ‚úÖ No existing ngrok processes found
[2025-08-28 20:22:46] 2025-08-28 20:22:46: ‚ùå Ngrok failed to start, checking logs...
[2025-08-28 20:22:46] 2025-08-28 20:22:46: üìÑ Ngrok log: t=2025-08-28T20:22:36+0000 lvl=info msg="no configuration paths supplied"
[2025-08-28 20:22:46] 2025-08-28 20:22:46: üìÑ Ngrok log: t=2025-08-28T20:22:36+0000 lvl=info msg="using configuration at default config path" path=/home/ubuntu/.config/ngrok/ngrok.yml
[2025-08-28 20:22:46] 2025-08-28 20:22:46: üìÑ Ngrok log: t=2025-08-28T20:22:36+0000 lvl=info msg="open config file" path=/home/ubuntu/.config/ngrok/ngrok.yml err=nil
[2025-08-28 20:22:46] 2025-08-28 20:22:46: üìÑ Ngrok log: ERROR:  You can't enable the console UI and log to stdout or stderr
[2025-08-28 20:22:46] 2025-08-28 20:22:46: üîÑ Retrying in 15 seconds...
[2025-08-28 20:23:01] 2025-08-28 20:23:01: üõë Received termination signal, cleaning up...
[2025-08-28 20:23:01] 2025-08-28 20:23:01: üõë Stopping Django...
[2025-08-28 20:23:01] 2025-08-28 20:23:01: ‚úÖ Cleanup complete
[2025-08-28 20:23:25] üöÄ Starting NoctisPro Auto-Startup Service
[2025-08-28 20:23:25] ============================================
[2025-08-28 20:23:25] Static Ngrok URL: https://colt-charmed-lark.ngrok-free.app
[2025-08-28 20:23:25] Workspace: /workspace
[2025-08-28 20:23:25] Started at: Thu Aug 28 08:23:25 PM UTC 2025
[2025-08-28 20:23:25] 2025-08-28 20:23:25: üèÅ Starting main startup sequence...
[2025-08-28 20:23:25] 2025-08-28 20:23:25: üêç Starting Django server...
[2025-08-28 20:23:25] 2025-08-28 20:23:25: ‚úÖ Virtual environment activated
[2025-08-28 20:23:25] 2025-08-28 20:23:25: üîÑ Running database migrations...
[2025-08-28 20:23:26] Traceback (most recent call last):
[2025-08-28 20:23:26]   File "/workspace/venv/lib/python3.13/site-packages/django/db/backends/base/base.py", line 279, in ensure_connection
[2025-08-28 20:23:26]     self.connect()
[2025-08-28 20:23:26]     ~~~~~~~~~~~~^^
[2025-08-28 20:23:26]   File "/workspace/venv/lib/python3.13/site-packages/django/utils/asyncio.py", line 26, in inner
[2025-08-28 20:23:26]     return func(*args, **kwargs)
[2025-08-28 20:23:26]   File "/workspace/venv/lib/python3.13/site-packages/django/db/backends/base/base.py", line 256, in connect
[2025-08-28 20:23:26]     self.connection = self.get_new_connection(conn_params)
[2025-08-28 20:23:26]                       ~~~~~~~~~~~~~~~~~~~~~~~^^^^^^^^^^^^^
[2025-08-28 20:23:26]   File "/workspace/venv/lib/python3.13/site-packages/django/utils/asyncio.py", line 26, in inner
[2025-08-28 20:23:26]     return func(*args, **kwargs)
[2025-08-28 20:23:26]   File "/workspace/venv/lib/python3.13/site-packages/django/db/backends/postgresql/base.py", line 332, in get_new_connection
[2025-08-28 20:23:26]     connection = self.Database.connect(**conn_params)
[2025-08-28 20:23:26]   File "/workspace/venv/lib/python3.13/site-packages/psycopg2/__init__.py", line 122, in connect
[2025-08-28 20:23:26]     conn = _connect(dsn, connection_factory=connection_factory, **kwasync)
[2025-08-28 20:23:26] psycopg2.OperationalError: connection to server at "localhost" (::1), port 5432 failed: Connection refused
[2025-08-28 20:23:26] 	Is the server running on that host and accepting TCP/IP connections?
[2025-08-28 20:23:26] connection to server at "localhost" (127.0.0.1), port 5432 failed: Connection refused
[2025-08-28 20:23:26] 	Is the server running on that host and accepting TCP/IP connections?
[2025-08-28 20:23:26] 
[2025-08-28 20:23:26] 
[2025-08-28 20:23:26] The above exception was the direct cause of the following exception:
[2025-08-28 20:23:26] 
[2025-08-28 20:23:26] Traceback (most recent call last):
[2025-08-28 20:23:26]   File "/workspace/manage.py", line 22, in <module>
[2025-08-28 20:23:26]     main()
[2025-08-28 20:23:26]     ~~~~^^
[2025-08-28 20:23:26]   File "/workspace/manage.py", line 18, in main
[2025-08-28 20:23:26]     execute_from_command_line(sys.argv)
[2025-08-28 20:23:26]     ~~~~~~~~~~~~~~~~~~~~~~~~~^^^^^^^^^^
[2025-08-28 20:23:26]   File "/workspace/venv/lib/python3.13/site-packages/django/core/management/__init__.py", line 442, in execute_from_command_line
[2025-08-28 20:23:26]     utility.execute()
[2025-08-28 20:23:26]     ~~~~~~~~~~~~~~~^^
[2025-08-28 20:23:26]   File "/workspace/venv/lib/python3.13/site-packages/django/core/management/__init__.py", line 436, in execute
[2025-08-28 20:23:26]     self.fetch_command(subcommand).run_from_argv(self.argv)
[2025-08-28 20:23:26]     ~~~~~~~~~~~~~~~~~~~~~~~~~~~~~~~~~~~~~~~~~~~~^^^^^^^^^^^
[2025-08-28 20:23:26]   File "/workspace/venv/lib/python3.13/site-packages/django/core/management/base.py", line 416, in run_from_argv
[2025-08-28 20:23:26]     self.execute(*args, **cmd_options)
[2025-08-28 20:23:26]     ~~~~~~~~~~~~^^^^^^^^^^^^^^^^^^^^^^
[2025-08-28 20:23:26]   File "/workspace/venv/lib/python3.13/site-packages/django/core/management/base.py", line 460, in execute
[2025-08-28 20:23:26]     output = self.handle(*args, **options)
[2025-08-28 20:23:26]   File "/workspace/venv/lib/python3.13/site-packages/django/core/management/base.py", line 107, in wrapper
[2025-08-28 20:23:26]     res = handle_func(*args, **kwargs)
[2025-08-28 20:23:26]   File "/workspace/venv/lib/python3.13/site-packages/django/core/management/commands/migrate.py", line 114, in handle
[2025-08-28 20:23:26]     executor = MigrationExecutor(connection, self.migration_progress_callback)
[2025-08-28 20:23:26]   File "/workspace/venv/lib/python3.13/site-packages/django/db/migrations/executor.py", line 18, in __init__
[2025-08-28 20:23:26]     self.loader = MigrationLoader(self.connection)
[2025-08-28 20:23:26]                   ~~~~~~~~~~~~~~~^^^^^^^^^^^^^^^^^
[2025-08-28 20:23:26]   File "/workspace/venv/lib/python3.13/site-packages/django/db/migrations/loader.py", line 58, in __init__
[2025-08-28 20:23:26]     self.build_graph()
[2025-08-28 20:23:26]     ~~~~~~~~~~~~~~~~^^
[2025-08-28 20:23:26]   File "/workspace/venv/lib/python3.13/site-packages/django/db/migrations/loader.py", line 235, in build_graph
[2025-08-28 20:23:26]     self.applied_migrations = recorder.applied_migrations()
[2025-08-28 20:23:26]                               ~~~~~~~~~~~~~~~~~~~~~~~~~~~^^
[2025-08-28 20:23:26]   File "/workspace/venv/lib/python3.13/site-packages/django/db/migrations/recorder.py", line 89, in applied_migrations
[2025-08-28 20:23:26]     if self.has_table():
[2025-08-28 20:23:26]        ~~~~~~~~~~~~~~^^
[2025-08-28 20:23:26]   File "/workspace/venv/lib/python3.13/site-packages/django/db/migrations/recorder.py", line 63, in has_table
[2025-08-28 20:23:26]     with self.connection.cursor() as cursor:
[2025-08-28 20:23:26]          ~~~~~~~~~~~~~~~~~~~~~~^^
[2025-08-28 20:23:26]   File "/workspace/venv/lib/python3.13/site-packages/django/utils/asyncio.py", line 26, in inner
[2025-08-28 20:23:26]     return func(*args, **kwargs)
[2025-08-28 20:23:26]   File "/workspace/venv/lib/python3.13/site-packages/django/db/backends/base/base.py", line 320, in cursor
[2025-08-28 20:23:26]     return self._cursor()
[2025-08-28 20:23:26]            ~~~~~~~~~~~~^^
[2025-08-28 20:23:26]   File "/workspace/venv/lib/python3.13/site-packages/django/db/backends/base/base.py", line 296, in _cursor
[2025-08-28 20:23:26]     self.ensure_connection()
[2025-08-28 20:23:26]     ~~~~~~~~~~~~~~~~~~~~~~^^
[2025-08-28 20:23:26]   File "/workspace/venv/lib/python3.13/site-packages/django/utils/asyncio.py", line 26, in inner
[2025-08-28 20:23:26]     return func(*args, **kwargs)
[2025-08-28 20:23:26]   File "/workspace/venv/lib/python3.13/site-packages/django/db/backends/base/base.py", line 278, in ensure_connection
[2025-08-28 20:23:26]     with self.wrap_database_errors:
[2025-08-28 20:23:26]          ^^^^^^^^^^^^^^^^^^^^^^^^^
[2025-08-28 20:23:26]   File "/workspace/venv/lib/python3.13/site-packages/django/db/utils.py", line 91, in __exit__
[2025-08-28 20:23:26]     raise dj_exc_value.with_traceback(traceback) from exc_value
[2025-08-28 20:23:26]   File "/workspace/venv/lib/python3.13/site-packages/django/db/backends/base/base.py", line 279, in ensure_connection
[2025-08-28 20:23:26]     self.connect()
[2025-08-28 20:23:26]     ~~~~~~~~~~~~^^
[2025-08-28 20:23:26]   File "/workspace/venv/lib/python3.13/site-packages/django/utils/asyncio.py", line 26, in inner
[2025-08-28 20:23:26]     return func(*args, **kwargs)
[2025-08-28 20:23:26]   File "/workspace/venv/lib/python3.13/site-packages/django/db/backends/base/base.py", line 256, in connect
[2025-08-28 20:23:26]     self.connection = self.get_new_connection(conn_params)
[2025-08-28 20:23:26]                       ~~~~~~~~~~~~~~~~~~~~~~~^^^^^^^^^^^^^
[2025-08-28 20:23:26]   File "/workspace/venv/lib/python3.13/site-packages/django/utils/asyncio.py", line 26, in inner
[2025-08-28 20:23:26]     return func(*args, **kwargs)
[2025-08-28 20:23:26]   File "/workspace/venv/lib/python3.13/site-packages/django/db/backends/postgresql/base.py", line 332, in get_new_connection
[2025-08-28 20:23:26]     connection = self.Database.connect(**conn_params)
[2025-08-28 20:23:26]   File "/workspace/venv/lib/python3.13/site-packages/psycopg2/__init__.py", line 122, in connect
[2025-08-28 20:23:26]     conn = _connect(dsn, connection_factory=connection_factory, **kwasync)
[2025-08-28 20:23:26] django.db.utils.OperationalError: connection to server at "localhost" (::1), port 5432 failed: Connection refused
[2025-08-28 20:23:26] 	Is the server running on that host and accepting TCP/IP connections?
[2025-08-28 20:23:26] connection to server at "localhost" (127.0.0.1), port 5432 failed: Connection refused
[2025-08-28 20:23:26] 	Is the server running on that host and accepting TCP/IP connections?
[2025-08-28 20:23:26] 
[2025-08-28 20:23:26] 2025-08-28 20:23:26: üìÇ Collecting static files...
[2025-08-28 20:23:26] 
[2025-08-28 20:23:26] 0 static files copied to '/workspace/staticfiles', 165 unmodified.
[2025-08-28 20:23:27] 2025-08-28 20:23:27: üåê Starting Django/Daphne server on port 8000...
[2025-08-28 20:23:32] 2025-08-28 20:23:32: ‚úÖ Django started successfully (PID: 7461)
[2025-08-28 20:23:32] 2025-08-28 20:23:32: ‚úÖ Django startup successful
[2025-08-28 20:23:32] 2025-08-28 20:23:32: üîç Waiting for service at http://localhost:8000/health/simple/...
[2025-08-28 20:23:32] 2025-08-28 20:23:32: ‚úÖ Service is ready at http://localhost:8000/health/simple/
[2025-08-28 20:23:32] 2025-08-28 20:23:32: ‚úÖ Django is responding to health checks
[2025-08-28 20:23:32] 2025-08-28 20:23:32: üåê Attempt 1/5: Starting ngrok with static URL...
[2025-08-28 20:23:32] 2025-08-28 20:23:32: üõë Checking for existing ngrok processes...
[2025-08-28 20:23:32] 2025-08-28 20:23:32: ‚úÖ No existing ngrok processes found
[2025-08-28 20:23:42] 2025-08-28 20:23:42: ‚úÖ Ngrok started successfully (PID: 7531)
[2025-08-28 20:23:42] 2025-08-28 20:23:42: ‚úÖ Ngrok startup successful
[2025-08-28 20:23:42] 2025-08-28 20:23:42: üîç Waiting for service at https://colt-charmed-lark.ngrok-free.app/health/simple/...
[2025-08-28 20:23:42] 2025-08-28 20:23:42: ‚úÖ Service is ready at https://colt-charmed-lark.ngrok-free.app/health/simple/
[2025-08-28 20:23:42] 2025-08-28 20:23:42: üéâ External access confirmed!
[2025-08-28 20:23:42] 
[2025-08-28 20:23:42] 2025-08-28 20:23:42: üåü NoctisPro is now running!
[2025-08-28 20:23:42] 2025-08-28 20:23:42: üåç Static URL: https://colt-charmed-lark.ngrok-free.app
[2025-08-28 20:23:42] 2025-08-28 20:23:42: üè† Local URL: http://localhost:8000
[2025-08-28 20:23:42] 2025-08-28 20:23:42: üìä Admin panel: https://colt-charmed-lark.ngrok-free.app/admin-panel/
[2025-08-28 20:23:42] 2025-08-28 20:23:42: üè• DICOM viewer: https://colt-charmed-lark.ngrok-free.app/dicom-viewer/
[2025-08-28 20:23:42] 2025-08-28 20:23:42: üìã Worklist: https://colt-charmed-lark.ngrok-free.app/worklist/
[2025-08-28 20:23:42] 
[2025-08-28 20:23:42] 2025-08-28 20:23:42: üëÅÔ∏è  Starting service monitoring...
[2025-08-28 20:29:37] üöÄ Starting NoctisPro Auto-Startup Service
[2025-08-28 20:29:37] ============================================
[2025-08-28 20:29:37] Static Ngrok URL: https://colt-charmed-lark.ngrok-free.app
[2025-08-28 20:29:37] Workspace: /workspace
[2025-08-28 20:29:37] Started at: Thu Aug 28 08:29:37 PM UTC 2025
[2025-08-28 20:29:37] 2025-08-28 20:29:37: üèÅ Starting main startup sequence...
[2025-08-28 20:29:37] 2025-08-28 20:29:37: üêç Starting Django server...
[2025-08-28 20:29:37] 2025-08-28 20:29:37: ‚ùå Virtual environment not found
[2025-08-28 20:29:37] 2025-08-28 20:29:37: ‚ùå Django startup failed, exiting
[2025-08-28 20:32:28] üöÄ Starting NoctisPro Auto-Startup Service
[2025-08-28 20:32:28] ============================================
[2025-08-28 20:32:28] Static Ngrok URL: https://colt-charmed-lark.ngrok-free.app
[2025-08-28 20:32:28] Workspace: /workspace
[2025-08-28 20:32:28] Started at: Thu Aug 28 08:32:28 PM UTC 2025
[2025-08-28 20:32:28] 2025-08-28 20:32:28: üèÅ Starting main startup sequence...
[2025-08-28 20:32:28] 2025-08-28 20:32:28: üêç Starting Django server...
[2025-08-28 20:32:28] 2025-08-28 20:32:28: ‚úÖ Django is available
[2025-08-28 20:32:28] 2025-08-28 20:32:28: üîÑ Running database migrations...
[2025-08-28 20:32:28] /workspace/autostart_noctispro.sh: line 145: python: command not found
[2025-08-28 20:32:28] 2025-08-28 20:32:28: üìÇ Collecting static files...
[2025-08-28 20:32:28] /workspace/autostart_noctispro.sh: line 149: python: command not found
[2025-08-28 20:32:28] 2025-08-28 20:32:28: üåê Starting Django/Daphne server on port 8000...
[2025-08-28 20:32:33] 2025-08-28 20:32:33: ‚úÖ Django started successfully (PID: 2669)
[2025-08-28 20:32:33] 2025-08-28 20:32:33: ‚úÖ Django startup successful
[2025-08-28 20:32:33] 2025-08-28 20:32:33: üîç Waiting for service at http://localhost:8000/health/simple/...
[2025-08-28 20:32:33] 2025-08-28 20:32:33: ‚úÖ Service is ready at http://localhost:8000/health/simple/
[2025-08-28 20:32:33] 2025-08-28 20:32:33: ‚úÖ Django is responding to health checks
[2025-08-28 20:32:33] 2025-08-28 20:32:33: üåê Attempt 1/5: Starting ngrok with static URL...
[2025-08-28 20:32:33] 2025-08-28 20:32:33: üõë Checking for existing ngrok processes...
[2025-08-28 20:32:33] 2025-08-28 20:32:33: ‚úÖ No existing ngrok processes found
[2025-08-28 20:32:43] 2025-08-28 20:32:43: ‚ùå Ngrok failed to start, checking logs...
[2025-08-28 20:32:43] 2025-08-28 20:32:43: üìÑ Ngrok log: nohup: failed to run command 'ngrok': No such file or directory
[2025-08-28 20:32:43] 2025-08-28 20:32:43: üîÑ Retrying in 15 seconds...
[2025-08-28 20:32:58] 2025-08-28 20:32:58: üåê Attempt 2/5: Starting ngrok with static URL...
[2025-08-28 20:32:58] 2025-08-28 20:32:58: üõë Checking for existing ngrok processes...
[2025-08-28 20:32:58] 2025-08-28 20:32:58: ‚úÖ No existing ngrok processes found
[2025-08-28 20:33:08] 2025-08-28 20:33:08: ‚ùå Ngrok failed to start, checking logs...
[2025-08-28 20:33:08] 2025-08-28 20:33:08: üìÑ Ngrok log: nohup: failed to run command 'ngrok': No such file or directory
[2025-08-28 20:33:08] 2025-08-28 20:33:08: üîÑ Retrying in 15 seconds...
[2025-08-28 20:33:23] 2025-08-28 20:33:23: üõë Received termination signal, cleaning up...
[2025-08-28 20:33:23] 2025-08-28 20:33:23: üõë Stopping Django...
[2025-08-28 20:33:23] 2025-08-28 20:33:23: ‚úÖ Cleanup complete
[2025-08-28 20:33:50] üöÄ Starting NoctisPro Auto-Startup Service
[2025-08-28 20:33:50] ============================================
[2025-08-28 20:33:50] Static Ngrok URL: https://colt-charmed-lark.ngrok-free.app
[2025-08-28 20:33:50] Workspace: /workspace
[2025-08-28 20:33:50] Started at: Thu Aug 28 08:33:50 PM UTC 2025
[2025-08-28 20:33:50] 2025-08-28 20:33:50: üèÅ Starting main startup sequence...
[2025-08-28 20:33:50] 2025-08-28 20:33:50: üêç Starting Django server...
[2025-08-28 20:33:50] 2025-08-28 20:33:50: ‚úÖ Django is available
[2025-08-28 20:33:50] 2025-08-28 20:33:50: üîÑ Running database migrations...
[2025-08-28 20:33:51] Operations to perform:
[2025-08-28 20:33:51]   Apply all migrations: accounts, admin, admin_panel, ai_analysis, auth, chat, contenttypes, notifications, reports, sessions, worklist
[2025-08-28 20:33:51] Running migrations:
[2025-08-28 20:33:51]   No migrations to apply.
[2025-08-28 20:33:51] 2025-08-28 20:33:51: üìÇ Collecting static files...
[2025-08-28 20:33:51] 
[2025-08-28 20:33:51] 163 static files copied to '/workspace/staticfiles', 2 unmodified.
[2025-08-28 20:33:51] 2025-08-28 20:33:51: üåê Starting Django/Daphne server on port 8000...
[2025-08-28 20:33:56] 2025-08-28 20:33:56: ‚úÖ Django started successfully (PID: 3294)
[2025-08-28 20:33:56] 2025-08-28 20:33:56: ‚úÖ Django startup successful
[2025-08-28 20:33:56] 2025-08-28 20:33:56: üîç Waiting for service at http://localhost:8000/health/simple/...
[2025-08-28 20:33:57] 2025-08-28 20:33:57: ‚úÖ Service is ready at http://localhost:8000/health/simple/
[2025-08-28 20:33:57] 2025-08-28 20:33:57: ‚úÖ Django is responding to health checks
[2025-08-28 20:33:57] 2025-08-28 20:33:57: üåê Attempt 1/5: Starting ngrok with static URL...
[2025-08-28 20:33:57] 2025-08-28 20:33:57: üõë Checking for existing ngrok processes...
[2025-08-28 20:33:57] 2025-08-28 20:33:57: ‚úÖ No existing ngrok processes found
[2025-08-28 20:34:07] 2025-08-28 20:34:07: ‚ùå Ngrok failed to start, checking logs...
[2025-08-28 20:34:07] 2025-08-28 20:34:07: üìÑ Ngrok log: ERROR:  Install your authtoken: https://dashboard.ngrok.com/get-started/your-authtoken
[2025-08-28 20:34:07] 2025-08-28 20:34:07: üìÑ Ngrok log: ERROR:  
[2025-08-28 20:34:07] 2025-08-28 20:34:07: üìÑ Ngrok log: ERROR:  ERR_NGROK_4018
[2025-08-28 20:34:07] 2025-08-28 20:34:07: üìÑ Ngrok log: ERROR:  https://ngrok.com/docs/errors/err_ngrok_4018
[2025-08-28 20:34:07] 2025-08-28 20:34:07: üìÑ Ngrok log: ERROR:
[2025-08-28 20:34:07] 2025-08-28 20:34:07: üîÑ Retrying in 15 seconds...
[2025-08-28 20:34:22] 2025-08-28 20:34:22: üåê Attempt 2/5: Starting ngrok with static URL...
[2025-08-28 20:34:22] 2025-08-28 20:34:22: üõë Checking for existing ngrok processes...
[2025-08-28 20:34:22] 2025-08-28 20:34:22: ‚úÖ No existing ngrok processes found
[2025-08-28 20:34:32] 2025-08-28 20:34:32: ‚ùå Ngrok failed to start, checking logs...
[2025-08-28 20:34:32] 2025-08-28 20:34:32: üìÑ Ngrok log: ERROR:  Install your authtoken: https://dashboard.ngrok.com/get-started/your-authtoken
[2025-08-28 20:34:32] 2025-08-28 20:34:32: üìÑ Ngrok log: ERROR:  
[2025-08-28 20:34:32] 2025-08-28 20:34:32: üìÑ Ngrok log: ERROR:  ERR_NGROK_4018
[2025-08-28 20:34:32] 2025-08-28 20:34:32: üìÑ Ngrok log: ERROR:  https://ngrok.com/docs/errors/err_ngrok_4018
[2025-08-28 20:34:32] 2025-08-28 20:34:32: üìÑ Ngrok log: ERROR:
[2025-08-28 20:34:32] 2025-08-28 20:34:32: üîÑ Retrying in 15 seconds...
[2025-08-28 20:34:47] 2025-08-28 20:34:47: üåê Attempt 3/5: Starting ngrok with static URL...
[2025-08-28 20:34:47] 2025-08-28 20:34:47: üõë Checking for existing ngrok processes...
[2025-08-28 20:34:47] 2025-08-28 20:34:47: ‚úÖ No existing ngrok processes found
[2025-08-28 20:34:57] 2025-08-28 20:34:57: ‚ùå Ngrok failed to start, checking logs...
[2025-08-28 20:34:57] 2025-08-28 20:34:57: üìÑ Ngrok log: ERROR:  Install your authtoken: https://dashboard.ngrok.com/get-started/your-authtoken
[2025-08-28 20:34:57] 2025-08-28 20:34:57: üìÑ Ngrok log: ERROR:  
[2025-08-28 20:34:57] 2025-08-28 20:34:57: üìÑ Ngrok log: ERROR:  ERR_NGROK_4018
[2025-08-28 20:34:57] 2025-08-28 20:34:57: üìÑ Ngrok log: ERROR:  https://ngrok.com/docs/errors/err_ngrok_4018
[2025-08-28 20:34:57] 2025-08-28 20:34:57: üìÑ Ngrok log: ERROR:
[2025-08-28 20:34:57] 2025-08-28 20:34:57: üîÑ Retrying in 15 seconds...
[2025-08-28 20:35:12] 2025-08-28 20:35:12: üåê Attempt 4/5: Starting ngrok with static URL...
[2025-08-28 20:35:12] 2025-08-28 20:35:12: üõë Checking for existing ngrok processes...
[2025-08-28 20:35:12] 2025-08-28 20:35:12: ‚úÖ No existing ngrok processes found
[2025-08-28 20:35:22] 2025-08-28 20:35:22: ‚ùå Ngrok failed to start, checking logs...
[2025-08-28 20:35:22] 2025-08-28 20:35:22: üìÑ Ngrok log: ERROR:  Install your authtoken: https://dashboard.ngrok.com/get-started/your-authtoken
[2025-08-28 20:35:22] 2025-08-28 20:35:22: üìÑ Ngrok log: ERROR:  
[2025-08-28 20:35:22] 2025-08-28 20:35:22: üìÑ Ngrok log: ERROR:  ERR_NGROK_4018
[2025-08-28 20:35:22] 2025-08-28 20:35:22: üìÑ Ngrok log: ERROR:  https://ngrok.com/docs/errors/err_ngrok_4018
[2025-08-28 20:35:22] 2025-08-28 20:35:22: üìÑ Ngrok log: ERROR:
[2025-08-28 20:35:22] 2025-08-28 20:35:22: üîÑ Retrying in 15 seconds...
[2025-08-28 20:35:37] 2025-08-28 20:35:37: üõë Received termination signal, cleaning up...
[2025-08-28 20:35:37] 2025-08-28 20:35:37: üõë Stopping Django...
[2025-08-28 20:35:37] 2025-08-28 20:35:37: ‚úÖ Cleanup complete
[2025-08-28 20:35:57] üöÄ Starting NoctisPro Auto-Startup Service
[2025-08-28 20:35:57] ============================================
[2025-08-28 20:35:57] Static Ngrok URL: https://colt-charmed-lark.ngrok-free.app
[2025-08-28 20:35:57] Workspace: /workspace
[2025-08-28 20:35:57] Started at: Thu Aug 28 08:35:57 PM UTC 2025
[2025-08-28 20:35:57] 2025-08-28 20:35:57: üèÅ Starting main startup sequence...
[2025-08-28 20:35:57] 2025-08-28 20:35:57: üêç Starting Django server...
[2025-08-28 20:35:57] 2025-08-28 20:35:57: ‚úÖ Django is available
[2025-08-28 20:35:57] 2025-08-28 20:35:57: üîÑ Running database migrations...
[2025-08-28 20:35:58] Operations to perform:
[2025-08-28 20:35:58]   Apply all migrations: accounts, admin, admin_panel, ai_analysis, auth, chat, contenttypes, notifications, reports, sessions, worklist
[2025-08-28 20:35:58] Running migrations:
[2025-08-28 20:35:58]   No migrations to apply.
[2025-08-28 20:35:58] 2025-08-28 20:35:58: üìÇ Collecting static files...
[2025-08-28 20:35:58] 
[2025-08-28 20:35:58] 0 static files copied to '/workspace/staticfiles', 165 unmodified.
[2025-08-28 20:35:58] 2025-08-28 20:35:58: üåê Starting Django/Daphne server on port 8000...
[2025-08-28 20:36:03] 2025-08-28 20:36:03: ‚úÖ Django started successfully (PID: 3909)
[2025-08-28 20:36:03] 2025-08-28 20:36:03: ‚úÖ Django startup successful
[2025-08-28 20:36:03] 2025-08-28 20:36:03: üîç Waiting for service at http://localhost:8000/health/simple/...
[2025-08-28 20:36:03] 2025-08-28 20:36:03: ‚úÖ Service is ready at http://localhost:8000/health/simple/
[2025-08-28 20:36:03] 2025-08-28 20:36:03: ‚úÖ Django is responding to health checks
[2025-08-28 20:36:03] 2025-08-28 20:36:03: üåê Attempt 1/5: Starting ngrok with static URL...
[2025-08-28 20:36:03] 2025-08-28 20:36:03: üõë Checking for existing ngrok processes...
[2025-08-28 20:36:03] 2025-08-28 20:36:03: ‚úÖ No existing ngrok processes found
[2025-08-28 20:36:03] 2025-08-28 20:36:03: ‚ö†Ô∏è  Ngrok not authenticated. Trying without custom domain...
[2025-08-28 20:36:13] 2025-08-28 20:36:13: ‚ùå Ngrok failed to start, checking logs...
[2025-08-28 20:36:13] 2025-08-28 20:36:13: üìÑ Ngrok log: ERROR:  Install your authtoken: https://dashboard.ngrok.com/get-started/your-authtoken
[2025-08-28 20:36:13] 2025-08-28 20:36:13: üìÑ Ngrok log: ERROR:  
[2025-08-28 20:36:13] 2025-08-28 20:36:13: üìÑ Ngrok log: ERROR:  ERR_NGROK_4018
[2025-08-28 20:36:13] 2025-08-28 20:36:13: üìÑ Ngrok log: ERROR:  https://ngrok.com/docs/errors/err_ngrok_4018
[2025-08-28 20:36:13] 2025-08-28 20:36:13: üìÑ Ngrok log: ERROR:
[2025-08-28 20:36:13] 2025-08-28 20:36:13: üîÑ Retrying in 15 seconds...
[2025-08-28 20:36:28] 2025-08-28 20:36:28: üåê Attempt 2/5: Starting ngrok with static URL...
[2025-08-28 20:36:28] 2025-08-28 20:36:28: üõë Checking for existing ngrok processes...
[2025-08-28 20:36:28] 2025-08-28 20:36:28: ‚úÖ No existing ngrok processes found
[2025-08-28 20:36:28] 2025-08-28 20:36:28: ‚ö†Ô∏è  Ngrok not authenticated. Trying without custom domain...
[2025-08-28 20:36:38] 2025-08-28 20:36:38: ‚ùå Ngrok failed to start, checking logs...
[2025-08-28 20:36:38] 2025-08-28 20:36:38: üìÑ Ngrok log: ERROR:  Install your authtoken: https://dashboard.ngrok.com/get-started/your-authtoken
[2025-08-28 20:36:38] 2025-08-28 20:36:38: üìÑ Ngrok log: ERROR:  
[2025-08-28 20:36:38] 2025-08-28 20:36:38: üìÑ Ngrok log: ERROR:  ERR_NGROK_4018
[2025-08-28 20:36:38] 2025-08-28 20:36:38: üìÑ Ngrok log: ERROR:  https://ngrok.com/docs/errors/err_ngrok_4018
[2025-08-28 20:36:38] 2025-08-28 20:36:38: üìÑ Ngrok log: ERROR:
[2025-08-28 20:36:38] 2025-08-28 20:36:38: üîÑ Retrying in 15 seconds...
[2025-08-28 20:36:53] 2025-08-28 20:36:53: üåê Attempt 3/5: Starting ngrok with static URL...
[2025-08-28 20:36:53] 2025-08-28 20:36:53: üõë Checking for existing ngrok processes...
[2025-08-28 20:36:53] 2025-08-28 20:36:53: ‚úÖ No existing ngrok processes found
[2025-08-28 20:36:53] 2025-08-28 20:36:53: ‚ö†Ô∏è  Ngrok not authenticated. Trying without custom domain...
[2025-08-28 20:37:03] 2025-08-28 20:37:03: üõë Received termination signal, cleaning up...
[2025-08-28 20:37:03] 2025-08-28 20:37:03: üõë Stopping Django...
[2025-08-28 20:37:03] 2025-08-28 20:37:03: ‚úÖ Cleanup complete
[2025-08-28 20:37:32] üöÄ Starting NoctisPro Auto-Startup Service
[2025-08-28 20:37:32] ============================================
[2025-08-28 20:37:32] Static Ngrok URL: https://colt-charmed-lark.ngrok-free.app
[2025-08-28 20:37:32] Workspace: /workspace
[2025-08-28 20:37:32] Started at: Thu Aug 28 08:37:32 PM UTC 2025
[2025-08-28 20:37:32] 2025-08-28 20:37:32: üèÅ Starting main startup sequence...
[2025-08-28 20:37:32] 2025-08-28 20:37:32: üêç Starting Django server...
[2025-08-28 20:37:32] 2025-08-28 20:37:32: ‚úÖ Django is available
[2025-08-28 20:37:32] 2025-08-28 20:37:32: üîÑ Running database migrations...
[2025-08-28 20:37:33] Operations to perform:
[2025-08-28 20:37:33]   Apply all migrations: accounts, admin, admin_panel, ai_analysis, auth, chat, contenttypes, notifications, reports, sessions, worklist
[2025-08-28 20:37:33] Running migrations:
[2025-08-28 20:37:33]   No migrations to apply.
[2025-08-28 20:37:33] 2025-08-28 20:37:33: üìÇ Collecting static files...
[2025-08-28 20:37:33] 
[2025-08-28 20:37:33] 0 static files copied to '/workspace/staticfiles', 165 unmodified.
[2025-08-28 20:37:33] 2025-08-28 20:37:33: üåê Starting Django/Daphne server on port 8000...
[2025-08-28 20:37:38] 2025-08-28 20:37:38: ‚úÖ Django started successfully (PID: 4452)
[2025-08-28 20:37:38] 2025-08-28 20:37:38: ‚úÖ Django startup successful
[2025-08-28 20:37:38] 2025-08-28 20:37:38: üîç Waiting for service at http://localhost:8000/health/simple/...
[2025-08-28 20:37:39] 2025-08-28 20:37:39: ‚úÖ Service is ready at http://localhost:8000/health/simple/
[2025-08-28 20:37:39] 2025-08-28 20:37:39: ‚úÖ Django is responding to health checks
[2025-08-28 20:37:39] 2025-08-28 20:37:39: üåê Attempt 1/5: Starting ngrok with static URL...
[2025-08-28 20:37:39] 2025-08-28 20:37:39: üõë Checking for existing ngrok processes...
[2025-08-28 20:37:39] 2025-08-28 20:37:39: ‚úÖ No existing ngrok processes found
[2025-08-28 20:37:39] 2025-08-28 20:37:39: ‚ö†Ô∏è  Ngrok not authenticated. Trying without custom domain...
[2025-08-28 20:37:49] 2025-08-28 20:37:49: ‚ùå Ngrok failed to start, checking logs...
[2025-08-28 20:37:49] 2025-08-28 20:37:49: üìÑ Ngrok log: ERROR:  Install your authtoken: https://dashboard.ngrok.com/get-started/your-authtoken
[2025-08-28 20:37:49] 2025-08-28 20:37:49: üìÑ Ngrok log: ERROR:  
[2025-08-28 20:37:49] 2025-08-28 20:37:49: üìÑ Ngrok log: ERROR:  ERR_NGROK_4018
[2025-08-28 20:37:49] 2025-08-28 20:37:49: üìÑ Ngrok log: ERROR:  https://ngrok.com/docs/errors/err_ngrok_4018
[2025-08-28 20:37:49] 2025-08-28 20:37:49: üìÑ Ngrok log: ERROR:
[2025-08-28 20:37:49] 2025-08-28 20:37:49: üîÑ Retrying in 15 seconds...
[2025-08-28 20:38:04] 2025-08-28 20:38:04: üåê Attempt 2/5: Starting ngrok with static URL...
[2025-08-28 20:38:04] 2025-08-28 20:38:04: üõë Checking for existing ngrok processes...
[2025-08-28 20:38:04] 2025-08-28 20:38:04: ‚úÖ No existing ngrok processes found
[2025-08-28 20:38:04] 2025-08-28 20:38:04: ‚ö†Ô∏è  Ngrok not authenticated. Trying without custom domain...
[2025-08-28 20:38:14] 2025-08-28 20:38:14: ‚ùå Ngrok failed to start, checking logs...
[2025-08-28 20:38:14] 2025-08-28 20:38:14: üìÑ Ngrok log: ERROR:  Install your authtoken: https://dashboard.ngrok.com/get-started/your-authtoken
[2025-08-28 20:38:14] 2025-08-28 20:38:14: üìÑ Ngrok log: ERROR:  
[2025-08-28 20:38:14] 2025-08-28 20:38:14: üìÑ Ngrok log: ERROR:  ERR_NGROK_4018
[2025-08-28 20:38:14] 2025-08-28 20:38:14: üìÑ Ngrok log: ERROR:  https://ngrok.com/docs/errors/err_ngrok_4018
[2025-08-28 20:38:14] 2025-08-28 20:38:14: üìÑ Ngrok log: ERROR:
[2025-08-28 20:38:14] 2025-08-28 20:38:14: üîÑ Retrying in 15 seconds...
[2025-08-28 20:38:29] 2025-08-28 20:38:29: üåê Attempt 3/5: Starting ngrok with static URL...
[2025-08-28 20:38:29] 2025-08-28 20:38:29: üõë Checking for existing ngrok processes...
[2025-08-28 20:38:29] 2025-08-28 20:38:29: ‚úÖ No existing ngrok processes found
[2025-08-28 20:38:29] 2025-08-28 20:38:29: ‚ö†Ô∏è  Ngrok not authenticated. Trying without custom domain...
[2025-08-28 20:38:39] 2025-08-28 20:38:39: ‚ùå Ngrok failed to start, checking logs...
[2025-08-28 20:38:39] 2025-08-28 20:38:39: üìÑ Ngrok log: ERROR:  Install your authtoken: https://dashboard.ngrok.com/get-started/your-authtoken
[2025-08-28 20:38:39] 2025-08-28 20:38:39: üìÑ Ngrok log: ERROR:  
[2025-08-28 20:38:39] 2025-08-28 20:38:39: üìÑ Ngrok log: ERROR:  ERR_NGROK_4018
[2025-08-28 20:38:39] 2025-08-28 20:38:39: üìÑ Ngrok log: ERROR:  https://ngrok.com/docs/errors/err_ngrok_4018
[2025-08-28 20:38:39] 2025-08-28 20:38:39: üìÑ Ngrok log: ERROR:
[2025-08-28 20:38:39] 2025-08-28 20:38:39: üîÑ Retrying in 15 seconds...
[2025-08-28 20:38:54] 2025-08-28 20:38:54: üåê Attempt 4/5: Starting ngrok with static URL...
[2025-08-28 20:38:54] 2025-08-28 20:38:54: üõë Checking for existing ngrok processes...
[2025-08-28 20:38:54] 2025-08-28 20:38:54: ‚úÖ No existing ngrok processes found
[2025-08-28 20:38:54] 2025-08-28 20:38:54: ‚ö†Ô∏è  Ngrok not authenticated. Trying without custom domain...
[2025-08-28 20:39:04] 2025-08-28 20:39:04: ‚ùå Ngrok failed to start, checking logs...
[2025-08-28 20:39:04] 2025-08-28 20:39:04: üìÑ Ngrok log: ERROR:  Install your authtoken: https://dashboard.ngrok.com/get-started/your-authtoken
[2025-08-28 20:39:04] 2025-08-28 20:39:04: üìÑ Ngrok log: ERROR:  
[2025-08-28 20:39:04] 2025-08-28 20:39:04: üìÑ Ngrok log: ERROR:  ERR_NGROK_4018
[2025-08-28 20:39:04] 2025-08-28 20:39:04: üìÑ Ngrok log: ERROR:  https://ngrok.com/docs/errors/err_ngrok_4018
[2025-08-28 20:39:04] 2025-08-28 20:39:04: üìÑ Ngrok log: ERROR:
[2025-08-28 20:39:04] 2025-08-28 20:39:04: üîÑ Retrying in 15 seconds...
[2025-08-28 20:39:19] 2025-08-28 20:39:19: üåê Attempt 5/5: Starting ngrok with static URL...
[2025-08-28 20:39:19] 2025-08-28 20:39:19: üõë Checking for existing ngrok processes...
[2025-08-28 20:39:19] 2025-08-28 20:39:19: ‚úÖ No existing ngrok processes found
[2025-08-28 20:39:19] 2025-08-28 20:39:19: ‚ö†Ô∏è  Ngrok not authenticated. Trying without custom domain...
[2025-08-28 20:39:29] 2025-08-28 20:39:29: ‚ùå Ngrok failed to start, checking logs...
[2025-08-28 20:39:29] 2025-08-28 20:39:29: üìÑ Ngrok log: ERROR:  Install your authtoken: https://dashboard.ngrok.com/get-started/your-authtoken
[2025-08-28 20:39:29] 2025-08-28 20:39:29: üìÑ Ngrok log: ERROR:  
[2025-08-28 20:39:29] 2025-08-28 20:39:29: üìÑ Ngrok log: ERROR:  ERR_NGROK_4018
[2025-08-28 20:39:29] 2025-08-28 20:39:29: üìÑ Ngrok log: ERROR:  https://ngrok.com/docs/errors/err_ngrok_4018
[2025-08-28 20:39:29] 2025-08-28 20:39:29: üìÑ Ngrok log: ERROR:
[2025-08-28 20:39:29] 2025-08-28 20:39:29: ‚ùå Failed to start ngrok after 5 attempts
[2025-08-28 20:39:29] 2025-08-28 20:39:29: ‚ö†Ô∏è  Ngrok startup failed - continuing without external tunnel
[2025-08-28 20:39:29] 2025-08-28 20:39:29: ‚ÑπÔ∏è  NoctisPro will run locally only. To enable external access:
[2025-08-28 20:39:29] 2025-08-28 20:39:29: ‚ÑπÔ∏è  1. Get a free ngrok account: https://dashboard.ngrok.com/signup
[2025-08-28 20:39:29] 2025-08-28 20:39:29: ‚ÑπÔ∏è  2. Get your auth token: https://dashboard.ngrok.com/get-started/your-authtoken
[2025-08-28 20:39:29] 2025-08-28 20:39:29: ‚ÑπÔ∏è  3. Run: ngrok config add-authtoken YOUR_TOKEN
[2025-08-28 20:39:29] 2025-08-28 20:39:29: ‚ÑπÔ∏è  4. Restart this service: ./manage_autostart.sh restart
[2025-08-28 20:39:29] 2025-08-28 20:39:29: ‚ÑπÔ∏è  Running in local mode (no external tunnel)
[2025-08-28 20:39:29] 
[2025-08-28 20:39:29] 2025-08-28 20:39:29: üåü NoctisPro is now running!
[2025-08-28 20:39:29] 2025-08-28 20:39:29: üåç External URL: http://localhost:8000
[2025-08-28 20:39:29] 2025-08-28 20:39:29: üè† Local URL: http://localhost:8000
[2025-08-28 20:39:29] 2025-08-28 20:39:29: üìä Admin panel: http://localhost:8000/admin-panel/
[2025-08-28 20:39:29] 2025-08-28 20:39:29: üè• DICOM viewer: http://localhost:8000/dicom-viewer/
[2025-08-28 20:39:29] 2025-08-28 20:39:29: üìã Worklist: http://localhost:8000/worklist/
[2025-08-28 20:39:29] 
[2025-08-28 20:39:29] 2025-08-28 20:39:29: üëÅÔ∏è  Starting service monitoring...
[2025-08-28 20:40:29] 2025-08-28 20:40:29: ‚ö†Ô∏è  Ngrok is not running, restarting...
[2025-08-28 20:40:29] 2025-08-28 20:40:29: üåê Attempt 1/5: Starting ngrok with static URL...
[2025-08-28 20:40:29] 2025-08-28 20:40:29: üõë Checking for existing ngrok processes...
[2025-08-28 20:40:29] 2025-08-28 20:40:29: ‚úÖ No existing ngrok processes found
[2025-08-28 20:40:29] 2025-08-28 20:40:29: ‚ö†Ô∏è  Ngrok not authenticated. Trying without custom domain...
[2025-08-28 20:40:39] 2025-08-28 20:40:39: ‚ùå Ngrok failed to start, checking logs...
[2025-08-28 20:40:39] 2025-08-28 20:40:39: üìÑ Ngrok log: ERROR:  Install your authtoken: https://dashboard.ngrok.com/get-started/your-authtoken
[2025-08-28 20:40:39] 2025-08-28 20:40:39: üìÑ Ngrok log: ERROR:  
[2025-08-28 20:40:39] 2025-08-28 20:40:39: üìÑ Ngrok log: ERROR:  ERR_NGROK_4018
[2025-08-28 20:40:39] 2025-08-28 20:40:39: üìÑ Ngrok log: ERROR:  https://ngrok.com/docs/errors/err_ngrok_4018
[2025-08-28 20:40:39] 2025-08-28 20:40:39: üìÑ Ngrok log: ERROR:
[2025-08-28 20:40:39] 2025-08-28 20:40:39: üîÑ Retrying in 15 seconds...
[2025-08-28 20:40:54] 2025-08-28 20:40:54: üåê Attempt 2/5: Starting ngrok with static URL...
[2025-08-28 20:40:54] 2025-08-28 20:40:54: üõë Checking for existing ngrok processes...
[2025-08-28 20:40:54] 2025-08-28 20:40:54: ‚úÖ No existing ngrok processes found
[2025-08-28 20:40:54] 2025-08-28 20:40:54: ‚ö†Ô∏è  Ngrok not authenticated. Trying without custom domain...
[2025-08-28 20:41:04] 2025-08-28 20:41:04: ‚ùå Ngrok failed to start, checking logs...
[2025-08-28 20:41:04] 2025-08-28 20:41:04: üìÑ Ngrok log: ERROR:  Install your authtoken: https://dashboard.ngrok.com/get-started/your-authtoken
[2025-08-28 20:41:04] 2025-08-28 20:41:04: üìÑ Ngrok log: ERROR:  
[2025-08-28 20:41:04] 2025-08-28 20:41:04: üìÑ Ngrok log: ERROR:  ERR_NGROK_4018
[2025-08-28 20:41:04] 2025-08-28 20:41:04: üìÑ Ngrok log: ERROR:  https://ngrok.com/docs/errors/err_ngrok_4018
[2025-08-28 20:41:04] 2025-08-28 20:41:04: üìÑ Ngrok log: ERROR:
[2025-08-28 20:41:04] 2025-08-28 20:41:04: üîÑ Retrying in 15 seconds...
[2025-08-28 20:41:19] 2025-08-28 20:41:19: üåê Attempt 3/5: Starting ngrok with static URL...
[2025-08-28 20:41:19] 2025-08-28 20:41:19: üõë Checking for existing ngrok processes...
[2025-08-28 20:41:19] 2025-08-28 20:41:19: ‚úÖ No existing ngrok processes found
[2025-08-28 20:41:19] 2025-08-28 20:41:19: ‚ö†Ô∏è  Ngrok not authenticated. Trying without custom domain...
[2025-08-28 20:41:29] 2025-08-28 20:41:29: ‚ùå Ngrok failed to start, checking logs...
[2025-08-28 20:41:29] 2025-08-28 20:41:29: üìÑ Ngrok log: ERROR:  Install your authtoken: https://dashboard.ngrok.com/get-started/your-authtoken
[2025-08-28 20:41:29] 2025-08-28 20:41:29: üìÑ Ngrok log: ERROR:  
[2025-08-28 20:41:29] 2025-08-28 20:41:29: üìÑ Ngrok log: ERROR:  ERR_NGROK_4018
[2025-08-28 20:41:29] 2025-08-28 20:41:29: üìÑ Ngrok log: ERROR:  https://ngrok.com/docs/errors/err_ngrok_4018
[2025-08-28 20:41:29] 2025-08-28 20:41:29: üìÑ Ngrok log: ERROR:
[2025-08-28 20:41:29] 2025-08-28 20:41:29: üîÑ Retrying in 15 seconds...
[2025-08-28 20:41:44] 2025-08-28 20:41:44: üåê Attempt 4/5: Starting ngrok with static URL...
[2025-08-28 20:41:44] 2025-08-28 20:41:44: üõë Checking for existing ngrok processes...
[2025-08-28 20:41:44] 2025-08-28 20:41:44: ‚úÖ No existing ngrok processes found
[2025-08-28 20:41:44] 2025-08-28 20:41:44: ‚ö†Ô∏è  Ngrok not authenticated. Trying without custom domain...
[2025-08-28 20:41:54] 2025-08-28 20:41:54: ‚ùå Ngrok failed to start, checking logs...
[2025-08-28 20:41:54] 2025-08-28 20:41:54: üìÑ Ngrok log: ERROR:  Install your authtoken: https://dashboard.ngrok.com/get-started/your-authtoken
[2025-08-28 20:41:54] 2025-08-28 20:41:54: üìÑ Ngrok log: ERROR:  
[2025-08-28 20:41:54] 2025-08-28 20:41:54: üìÑ Ngrok log: ERROR:  ERR_NGROK_4018
[2025-08-28 20:41:54] 2025-08-28 20:41:54: üìÑ Ngrok log: ERROR:  https://ngrok.com/docs/errors/err_ngrok_4018
[2025-08-28 20:41:54] 2025-08-28 20:41:54: üìÑ Ngrok log: ERROR:
[2025-08-28 20:41:54] 2025-08-28 20:41:54: üîÑ Retrying in 15 seconds...
[2025-08-28 20:42:09] 2025-08-28 20:42:09: üåê Attempt 5/5: Starting ngrok with static URL...
[2025-08-28 20:42:09] 2025-08-28 20:42:09: üõë Checking for existing ngrok processes...
[2025-08-28 20:42:09] 2025-08-28 20:42:09: ‚úÖ No existing ngrok processes found
[2025-08-28 20:42:09] 2025-08-28 20:42:09: ‚ö†Ô∏è  Ngrok not authenticated. Trying without custom domain...
[2025-08-28 20:42:19] 2025-08-28 20:42:19: ‚ùå Ngrok failed to start, checking logs...
[2025-08-28 20:42:19] 2025-08-28 20:42:19: üìÑ Ngrok log: ERROR:  Install your authtoken: https://dashboard.ngrok.com/get-started/your-authtoken
[2025-08-28 20:42:19] 2025-08-28 20:42:19: üìÑ Ngrok log: ERROR:  
[2025-08-28 20:42:19] 2025-08-28 20:42:19: üìÑ Ngrok log: ERROR:  ERR_NGROK_4018
[2025-08-28 20:42:19] 2025-08-28 20:42:19: üìÑ Ngrok log: ERROR:  https://ngrok.com/docs/errors/err_ngrok_4018
[2025-08-28 20:42:19] 2025-08-28 20:42:19: üìÑ Ngrok log: ERROR:
[2025-08-28 20:42:19] 2025-08-28 20:42:19: ‚ùå Failed to start ngrok after 5 attempts
